[2025-07-27T22:10:46.459+0000] {local_task_job_runner.py:120} INFO - ::group::Pre task execution logs
[2025-07-27T22:10:46.504+0000] {taskinstance.py:2073} INFO - Dependencies all met for dep_context=non-requeueable deps ti=<TaskInstance: monitoring_hourly.generate_monitoring_report scheduled__2025-07-27T21:00:00+00:00 [queued]>
[2025-07-27T22:10:46.514+0000] {taskinstance.py:2073} INFO - Dependencies all met for dep_context=requeueable deps ti=<TaskInstance: monitoring_hourly.generate_monitoring_report scheduled__2025-07-27T21:00:00+00:00 [queued]>
[2025-07-27T22:10:46.515+0000] {taskinstance.py:2303} INFO - Starting attempt 1 of 2
[2025-07-27T22:10:46.532+0000] {taskinstance.py:2327} INFO - Executing <Task(PythonOperator): generate_monitoring_report> on 2025-07-27 21:00:00+00:00
[2025-07-27T22:10:46.548+0000] {logging_mixin.py:188} WARNING - /home/***/.local/lib/python3.12/site-packages/***/task/task_runner/standard_task_runner.py:61 DeprecationWarning: This process (pid=909) is multi-threaded, use of fork() may lead to deadlocks in the child.
[2025-07-27T22:10:46.548+0000] {standard_task_runner.py:90} INFO - Running: ['***', 'tasks', 'run', 'monitoring_hourly', 'generate_monitoring_report', 'scheduled__2025-07-27T21:00:00+00:00', '--job-id', '9', '--raw', '--subdir', 'DAGS_FOLDER/daily_monitoring.py', '--cfg-path', '/tmp/tmpcoakqjvd']
[2025-07-27T22:10:46.550+0000] {standard_task_runner.py:63} INFO - Started process 949 to run task
[2025-07-27T22:10:46.550+0000] {standard_task_runner.py:91} INFO - Job 9: Subtask generate_monitoring_report
[2025-07-27T22:10:46.569+0000] {logging_mixin.py:188} WARNING - /home/***/.local/lib/python3.12/site-packages/***/settings.py:195 DeprecationWarning: The sql_alchemy_conn option in [core] has been moved to the sql_alchemy_conn option in [database] - the old setting has been used, but please update your config.
[2025-07-27T22:10:46.625+0000] {task_command.py:426} INFO - Running <TaskInstance: monitoring_hourly.generate_monitoring_report scheduled__2025-07-27T21:00:00+00:00 [running]> on host d34f55041ab8
[2025-07-27T22:10:46.727+0000] {taskinstance.py:2644} INFO - Exporting env vars: AIRFLOW_CTX_DAG_OWNER='mlops' AIRFLOW_CTX_DAG_ID='monitoring_hourly' AIRFLOW_CTX_TASK_ID='generate_monitoring_report' AIRFLOW_CTX_EXECUTION_DATE='2025-07-27T21:00:00+00:00' AIRFLOW_CTX_TRY_NUMBER='1' AIRFLOW_CTX_DAG_RUN_ID='scheduled__2025-07-27T21:00:00+00:00'
[2025-07-27T22:10:46.729+0000] {taskinstance.py:430} INFO - ::endgroup::
[2025-07-27T22:10:46.743+0000] {logging_mixin.py:188} WARNING - /home/***/.local/lib/python3.12/site-packages/***/utils/context.py:320 AirflowContextDeprecationWarning: Accessing 'execution_date' from the template is deprecated and will be removed in a future version. Please use 'data_interval_start' or 'logical_date' instead.
[2025-07-27T22:10:46.744+0000] {daily_monitoring.py:53} INFO - Monitoring for new data 2025-07-27 21 vs historic 2025-07-26 21
[2025-07-27T22:10:46.767+0000] {taskinstance.py:441} INFO - ::group::Post task execution logs
[2025-07-27T22:10:46.768+0000] {taskinstance.py:2890} ERROR - Task failed with exception
Traceback (most recent call last):
  File "/home/airflow/.local/lib/python3.12/site-packages/airflow/models/taskinstance.py", line 465, in _execute_task
    result = _execute_callable(context=context, **execute_callable_kwargs)
             ^^^^^^^^^^^^^^^^^^^^^^^^^^^^^^^^^^^^^^^^^^^^^^^^^^^^^^^^^^^^^
  File "/home/airflow/.local/lib/python3.12/site-packages/airflow/models/taskinstance.py", line 432, in _execute_callable
    return execute_callable(context=context, **execute_callable_kwargs)
           ^^^^^^^^^^^^^^^^^^^^^^^^^^^^^^^^^^^^^^^^^^^^^^^^^^^^^^^^^^^^
  File "/home/airflow/.local/lib/python3.12/site-packages/airflow/models/baseoperator.py", line 400, in wrapper
    return func(self, *args, **kwargs)
           ^^^^^^^^^^^^^^^^^^^^^^^^^^^
  File "/home/airflow/.local/lib/python3.12/site-packages/airflow/operators/python.py", line 235, in execute
    return_value = self.execute_callable()
                   ^^^^^^^^^^^^^^^^^^^^^^^
  File "/home/airflow/.local/lib/python3.12/site-packages/airflow/operators/python.py", line 252, in execute_callable
    return self.python_callable(*self.op_args, **self.op_kwargs)
           ^^^^^^^^^^^^^^^^^^^^^^^^^^^^^^^^^^^^^^^^^^^^^^^^^^^^^
  File "/opt/airflow/dags/daily_monitoring.py", line 67, in generate_monitoring_report
    df_features_new = load_s3_df(key_features_new)
                      ^^^^^^^^^^^^^^^^^^^^^^^^^^^^
  File "/opt/airflow/dags/daily_monitoring.py", line 56, in load_s3_df
    obj = s3_client.get_object(Bucket=S3_BUCKET, Key=key)
          ^^^^^^^^^^^^^^^^^^^^^^^^^^^^^^^^^^^^^^^^^^^^^^^
  File "/home/airflow/.local/lib/python3.12/site-packages/botocore/client.py", line 569, in _api_call
    return self._make_api_call(operation_name, kwargs)
           ^^^^^^^^^^^^^^^^^^^^^^^^^^^^^^^^^^^^^^^^^^^
  File "/home/airflow/.local/lib/python3.12/site-packages/botocore/client.py", line 1023, in _make_api_call
    raise error_class(parsed_response, operation_name)
botocore.errorfactory.NoSuchBucket: An error occurred (NoSuchBucket) when calling the GetObject operation: The specified bucket does not exist
[2025-07-27T22:10:46.787+0000] {taskinstance.py:1205} INFO - Marking task as UP_FOR_RETRY. dag_id=monitoring_hourly, task_id=generate_monitoring_report, execution_date=20250727T210000, start_date=20250727T221046, end_date=20250727T221046
[2025-07-27T22:10:46.803+0000] {standard_task_runner.py:110} ERROR - Failed to execute job 9 for task generate_monitoring_report (An error occurred (NoSuchBucket) when calling the GetObject operation: The specified bucket does not exist; 949)
[2025-07-27T22:10:46.846+0000] {local_task_job_runner.py:240} INFO - Task exited with return code 1
[2025-07-27T22:10:46.865+0000] {taskinstance.py:3482} INFO - 0 downstream tasks scheduled from follow-on schedule check
[2025-07-27T22:10:46.867+0000] {local_task_job_runner.py:222} INFO - ::endgroup::
[2025-07-27T22:21:34.297+0000] {local_task_job_runner.py:120} INFO - ::group::Pre task execution logs
[2025-07-27T22:21:34.331+0000] {taskinstance.py:2073} INFO - Dependencies all met for dep_context=non-requeueable deps ti=<TaskInstance: monitoring_hourly.generate_monitoring_report scheduled__2025-07-27T21:00:00+00:00 [queued]>
[2025-07-27T22:21:34.339+0000] {taskinstance.py:2073} INFO - Dependencies all met for dep_context=requeueable deps ti=<TaskInstance: monitoring_hourly.generate_monitoring_report scheduled__2025-07-27T21:00:00+00:00 [queued]>
[2025-07-27T22:21:34.340+0000] {taskinstance.py:2303} INFO - Starting attempt 1 of 2
[2025-07-27T22:21:34.351+0000] {taskinstance.py:2327} INFO - Executing <Task(PythonOperator): generate_monitoring_report> on 2025-07-27 21:00:00+00:00
[2025-07-27T22:21:34.364+0000] {logging_mixin.py:188} WARNING - /home/***/.local/lib/python3.12/site-packages/***/task/task_runner/standard_task_runner.py:61 DeprecationWarning: This process (pid=850) is multi-threaded, use of fork() may lead to deadlocks in the child.
[2025-07-27T22:21:34.364+0000] {standard_task_runner.py:90} INFO - Running: ['***', 'tasks', 'run', 'monitoring_hourly', 'generate_monitoring_report', 'scheduled__2025-07-27T21:00:00+00:00', '--job-id', '9', '--raw', '--subdir', 'DAGS_FOLDER/daily_monitoring.py', '--cfg-path', '/tmp/tmphp5cz1xo']
[2025-07-27T22:21:34.366+0000] {standard_task_runner.py:63} INFO - Started process 867 to run task
[2025-07-27T22:21:34.367+0000] {standard_task_runner.py:91} INFO - Job 9: Subtask generate_monitoring_report
[2025-07-27T22:21:34.384+0000] {logging_mixin.py:188} WARNING - /home/***/.local/lib/python3.12/site-packages/***/settings.py:195 DeprecationWarning: The sql_alchemy_conn option in [core] has been moved to the sql_alchemy_conn option in [database] - the old setting has been used, but please update your config.
[2025-07-27T22:21:34.426+0000] {task_command.py:426} INFO - Running <TaskInstance: monitoring_hourly.generate_monitoring_report scheduled__2025-07-27T21:00:00+00:00 [running]> on host 032d4e4c6301
[2025-07-27T22:21:34.724+0000] {taskinstance.py:2644} INFO - Exporting env vars: AIRFLOW_CTX_DAG_OWNER='mlops' AIRFLOW_CTX_DAG_ID='monitoring_hourly' AIRFLOW_CTX_TASK_ID='generate_monitoring_report' AIRFLOW_CTX_EXECUTION_DATE='2025-07-27T21:00:00+00:00' AIRFLOW_CTX_TRY_NUMBER='1' AIRFLOW_CTX_DAG_RUN_ID='scheduled__2025-07-27T21:00:00+00:00'
[2025-07-27T22:21:34.725+0000] {taskinstance.py:430} INFO - ::endgroup::
[2025-07-27T22:21:34.735+0000] {logging_mixin.py:188} WARNING - /home/***/.local/lib/python3.12/site-packages/***/utils/context.py:320 AirflowContextDeprecationWarning: Accessing 'execution_date' from the template is deprecated and will be removed in a future version. Please use 'data_interval_start' or 'logical_date' instead.
[2025-07-27T22:21:34.736+0000] {daily_monitoring.py:60} INFO - Monitoring for new data 2025-07-27 21 vs historic 2025-07-26 21
[2025-07-27T22:21:34.809+0000] {taskinstance.py:441} INFO - ::group::Post task execution logs
[2025-07-27T22:21:34.810+0000] {taskinstance.py:2890} ERROR - Task failed with exception
Traceback (most recent call last):
  File "/home/airflow/.local/lib/python3.12/site-packages/airflow/models/taskinstance.py", line 465, in _execute_task
    result = _execute_callable(context=context, **execute_callable_kwargs)
             ^^^^^^^^^^^^^^^^^^^^^^^^^^^^^^^^^^^^^^^^^^^^^^^^^^^^^^^^^^^^^
  File "/home/airflow/.local/lib/python3.12/site-packages/airflow/models/taskinstance.py", line 432, in _execute_callable
    return execute_callable(context=context, **execute_callable_kwargs)
           ^^^^^^^^^^^^^^^^^^^^^^^^^^^^^^^^^^^^^^^^^^^^^^^^^^^^^^^^^^^^
  File "/home/airflow/.local/lib/python3.12/site-packages/airflow/models/baseoperator.py", line 400, in wrapper
    return func(self, *args, **kwargs)
           ^^^^^^^^^^^^^^^^^^^^^^^^^^^
  File "/home/airflow/.local/lib/python3.12/site-packages/airflow/operators/python.py", line 235, in execute
    return_value = self.execute_callable()
                   ^^^^^^^^^^^^^^^^^^^^^^^
  File "/home/airflow/.local/lib/python3.12/site-packages/airflow/operators/python.py", line 252, in execute_callable
    return self.python_callable(*self.op_args, **self.op_kwargs)
           ^^^^^^^^^^^^^^^^^^^^^^^^^^^^^^^^^^^^^^^^^^^^^^^^^^^^^
  File "/opt/airflow/dags/daily_monitoring.py", line 76, in generate_monitoring_report
    df_features_hist = load_s3_df(key_features_hist)
                       ^^^^^^^^^^^^^^^^^^^^^^^^^^^^^
  File "/opt/airflow/dags/daily_monitoring.py", line 63, in load_s3_df
    obj = s3_client.get_object(Bucket=BUCKET_NAME, Key=key)
          ^^^^^^^^^^^^^^^^^^^^^^^^^^^^^^^^^^^^^^^^^^^^^^^^^
  File "/home/airflow/.local/lib/python3.12/site-packages/botocore/client.py", line 569, in _api_call
    return self._make_api_call(operation_name, kwargs)
           ^^^^^^^^^^^^^^^^^^^^^^^^^^^^^^^^^^^^^^^^^^^
  File "/home/airflow/.local/lib/python3.12/site-packages/botocore/client.py", line 1023, in _make_api_call
    raise error_class(parsed_response, operation_name)
botocore.errorfactory.NoSuchKey: An error occurred (NoSuchKey) when calling the GetObject operation: The specified key does not exist.
[2025-07-27T22:21:34.829+0000] {taskinstance.py:1205} INFO - Marking task as UP_FOR_RETRY. dag_id=monitoring_hourly, task_id=generate_monitoring_report, execution_date=20250727T210000, start_date=20250727T222134, end_date=20250727T222134
[2025-07-27T22:21:34.845+0000] {standard_task_runner.py:110} ERROR - Failed to execute job 9 for task generate_monitoring_report (An error occurred (NoSuchKey) when calling the GetObject operation: The specified key does not exist.; 867)
[2025-07-27T22:21:34.905+0000] {local_task_job_runner.py:240} INFO - Task exited with return code 1
[2025-07-27T22:21:34.924+0000] {taskinstance.py:3482} INFO - 0 downstream tasks scheduled from follow-on schedule check
[2025-07-27T22:21:34.928+0000] {local_task_job_runner.py:222} INFO - ::endgroup::
