[2025-07-27T22:26:44.247+0000] {local_task_job_runner.py:120} INFO - ::group::Pre task execution logs
[2025-07-27T22:26:44.296+0000] {taskinstance.py:2073} INFO - Dependencies all met for dep_context=non-requeueable deps ti=<TaskInstance: monitoring_hourly.generate_monitoring_report manual__2025-07-27T22:21:32.393753+00:00 [queued]>
[2025-07-27T22:26:44.309+0000] {taskinstance.py:2073} INFO - Dependencies all met for dep_context=requeueable deps ti=<TaskInstance: monitoring_hourly.generate_monitoring_report manual__2025-07-27T22:21:32.393753+00:00 [queued]>
[2025-07-27T22:26:44.311+0000] {taskinstance.py:2303} INFO - Starting attempt 1 of 2
[2025-07-27T22:26:44.330+0000] {taskinstance.py:2327} INFO - Executing <Task(PythonOperator): generate_monitoring_report> on 2025-07-27 22:21:32.393753+00:00
[2025-07-27T22:26:44.348+0000] {standard_task_runner.py:90} INFO - Running: ['***', 'tasks', 'run', 'monitoring_hourly', 'generate_monitoring_report', 'manual__2025-07-27T22:21:32.393753+00:00', '--job-id', '11', '--raw', '--subdir', 'DAGS_FOLDER/daily_monitoring.py', '--cfg-path', '/tmp/tmp0y0_6eid']
[2025-07-27T22:26:44.349+0000] {logging_mixin.py:188} WARNING - /home/***/.local/lib/python3.12/site-packages/***/task/task_runner/standard_task_runner.py:61 DeprecationWarning: This process (pid=1589) is multi-threaded, use of fork() may lead to deadlocks in the child.
[2025-07-27T22:26:44.351+0000] {standard_task_runner.py:91} INFO - Job 11: Subtask generate_monitoring_report
[2025-07-27T22:26:44.351+0000] {standard_task_runner.py:63} INFO - Started process 1610 to run task
[2025-07-27T22:26:44.368+0000] {logging_mixin.py:188} WARNING - /home/***/.local/lib/python3.12/site-packages/***/settings.py:195 DeprecationWarning: The sql_alchemy_conn option in [core] has been moved to the sql_alchemy_conn option in [database] - the old setting has been used, but please update your config.
[2025-07-27T22:26:44.416+0000] {task_command.py:426} INFO - Running <TaskInstance: monitoring_hourly.generate_monitoring_report manual__2025-07-27T22:21:32.393753+00:00 [running]> on host 032d4e4c6301
[2025-07-27T22:26:45.268+0000] {taskinstance.py:2644} INFO - Exporting env vars: AIRFLOW_CTX_DAG_OWNER='mlops' AIRFLOW_CTX_DAG_ID='monitoring_hourly' AIRFLOW_CTX_TASK_ID='generate_monitoring_report' AIRFLOW_CTX_EXECUTION_DATE='2025-07-27T22:21:32.393753+00:00' AIRFLOW_CTX_TRY_NUMBER='1' AIRFLOW_CTX_DAG_RUN_ID='manual__2025-07-27T22:21:32.393753+00:00'
[2025-07-27T22:26:45.271+0000] {taskinstance.py:430} INFO - ::endgroup::
[2025-07-27T22:26:45.309+0000] {logging_mixin.py:188} WARNING - /home/***/.local/lib/python3.12/site-packages/***/utils/context.py:320 AirflowContextDeprecationWarning: Accessing 'execution_date' from the template is deprecated and will be removed in a future version. Please use 'data_interval_start' or 'logical_date' instead.
[2025-07-27T22:26:45.310+0000] {daily_monitoring.py:60} INFO - Monitoring for new data 2025-07-27 22 vs historic 2025-07-26 22
[2025-07-27T22:26:45.517+0000] {taskinstance.py:441} INFO - ::group::Post task execution logs
[2025-07-27T22:26:45.519+0000] {taskinstance.py:2890} ERROR - Task failed with exception
Traceback (most recent call last):
  File "/home/airflow/.local/lib/python3.12/site-packages/airflow/models/taskinstance.py", line 465, in _execute_task
    result = _execute_callable(context=context, **execute_callable_kwargs)
             ^^^^^^^^^^^^^^^^^^^^^^^^^^^^^^^^^^^^^^^^^^^^^^^^^^^^^^^^^^^^^
  File "/home/airflow/.local/lib/python3.12/site-packages/airflow/models/taskinstance.py", line 432, in _execute_callable
    return execute_callable(context=context, **execute_callable_kwargs)
           ^^^^^^^^^^^^^^^^^^^^^^^^^^^^^^^^^^^^^^^^^^^^^^^^^^^^^^^^^^^^
  File "/home/airflow/.local/lib/python3.12/site-packages/airflow/models/baseoperator.py", line 400, in wrapper
    return func(self, *args, **kwargs)
           ^^^^^^^^^^^^^^^^^^^^^^^^^^^
  File "/home/airflow/.local/lib/python3.12/site-packages/airflow/operators/python.py", line 235, in execute
    return_value = self.execute_callable()
                   ^^^^^^^^^^^^^^^^^^^^^^^
  File "/home/airflow/.local/lib/python3.12/site-packages/airflow/operators/python.py", line 252, in execute_callable
    return self.python_callable(*self.op_args, **self.op_kwargs)
           ^^^^^^^^^^^^^^^^^^^^^^^^^^^^^^^^^^^^^^^^^^^^^^^^^^^^^
  File "/opt/airflow/dags/daily_monitoring.py", line 76, in generate_monitoring_report
    df_features_hist = load_s3_df(key_features_hist)
                       ^^^^^^^^^^^^^^^^^^^^^^^^^^^^^
  File "/opt/airflow/dags/daily_monitoring.py", line 63, in load_s3_df
    obj = s3_client.get_object(Bucket=BUCKET_NAME, Key=key)
          ^^^^^^^^^^^^^^^^^^^^^^^^^^^^^^^^^^^^^^^^^^^^^^^^^
  File "/home/airflow/.local/lib/python3.12/site-packages/botocore/client.py", line 569, in _api_call
    return self._make_api_call(operation_name, kwargs)
           ^^^^^^^^^^^^^^^^^^^^^^^^^^^^^^^^^^^^^^^^^^^
  File "/home/airflow/.local/lib/python3.12/site-packages/botocore/client.py", line 1023, in _make_api_call
    raise error_class(parsed_response, operation_name)
botocore.errorfactory.NoSuchKey: An error occurred (NoSuchKey) when calling the GetObject operation: The specified key does not exist.
[2025-07-27T22:26:45.592+0000] {taskinstance.py:1205} INFO - Marking task as UP_FOR_RETRY. dag_id=monitoring_hourly, task_id=generate_monitoring_report, execution_date=20250727T222132, start_date=20250727T222644, end_date=20250727T222645
[2025-07-27T22:26:45.640+0000] {standard_task_runner.py:110} ERROR - Failed to execute job 11 for task generate_monitoring_report (An error occurred (NoSuchKey) when calling the GetObject operation: The specified key does not exist.; 1610)
[2025-07-27T22:26:45.733+0000] {local_task_job_runner.py:240} INFO - Task exited with return code 1
[2025-07-27T22:26:45.778+0000] {taskinstance.py:3482} INFO - 0 downstream tasks scheduled from follow-on schedule check
[2025-07-27T22:26:45.782+0000] {local_task_job_runner.py:222} INFO - ::endgroup::
