[2025-07-27T19:44:55.990+0000] {local_task_job_runner.py:120} INFO - ::group::Pre task execution logs
[2025-07-27T19:44:56.029+0000] {taskinstance.py:2073} INFO - Dependencies all met for dep_context=non-requeueable deps ti=<TaskInstance: data_drift_monitoring.check_drift scheduled__2025-07-27T18:00:00+00:00 [queued]>
[2025-07-27T19:44:56.038+0000] {taskinstance.py:2073} INFO - Dependencies all met for dep_context=requeueable deps ti=<TaskInstance: data_drift_monitoring.check_drift scheduled__2025-07-27T18:00:00+00:00 [queued]>
[2025-07-27T19:44:56.074+0000] {taskinstance.py:2303} INFO - Starting attempt 1 of 1
[2025-07-27T19:44:56.091+0000] {taskinstance.py:2327} INFO - Executing <Task(PythonOperator): check_drift> on 2025-07-27 18:00:00+00:00
[2025-07-27T19:44:56.105+0000] {logging_mixin.py:188} WARNING - /home/***/.local/lib/python3.12/site-packages/***/task/task_runner/standard_task_runner.py:61 DeprecationWarning: This process (pid=879) is multi-threaded, use of fork() may lead to deadlocks in the child.
[2025-07-27T19:44:56.107+0000] {standard_task_runner.py:63} INFO - Started process 881 to run task
[2025-07-27T19:44:56.105+0000] {standard_task_runner.py:90} INFO - Running: ['***', 'tasks', 'run', 'data_drift_monitoring', 'check_drift', 'scheduled__2025-07-27T18:00:00+00:00', '--job-id', '9', '--raw', '--subdir', 'DAGS_FOLDER/drift_monitoring.py', '--cfg-path', '/tmp/tmpuq2qt6z7']
[2025-07-27T19:44:56.108+0000] {standard_task_runner.py:91} INFO - Job 9: Subtask check_drift
[2025-07-27T19:44:56.128+0000] {logging_mixin.py:188} WARNING - /home/***/.local/lib/python3.12/site-packages/***/settings.py:195 DeprecationWarning: The sql_alchemy_conn option in [core] has been moved to the sql_alchemy_conn option in [database] - the old setting has been used, but please update your config.
[2025-07-27T19:44:56.175+0000] {task_command.py:426} INFO - Running <TaskInstance: data_drift_monitoring.check_drift scheduled__2025-07-27T18:00:00+00:00 [running]> on host d1e83e43e29f
[2025-07-27T19:44:56.338+0000] {taskinstance.py:2644} INFO - Exporting env vars: AIRFLOW_CTX_DAG_EMAIL='salima.mamma25@gmail.com' AIRFLOW_CTX_DAG_OWNER='mlops' AIRFLOW_CTX_DAG_ID='data_drift_monitoring' AIRFLOW_CTX_TASK_ID='check_drift' AIRFLOW_CTX_EXECUTION_DATE='2025-07-27T18:00:00+00:00' AIRFLOW_CTX_TRY_NUMBER='1' AIRFLOW_CTX_DAG_RUN_ID='scheduled__2025-07-27T18:00:00+00:00'
[2025-07-27T19:44:56.341+0000] {taskinstance.py:430} INFO - ::endgroup::
[2025-07-27T19:44:56.366+0000] {logging_mixin.py:188} WARNING - /home/***/.local/lib/python3.12/site-packages/***/utils/context.py:320 AirflowContextDeprecationWarning: Accessing 'execution_date' from the template is deprecated and will be removed in a future version. Please use 'data_interval_start' or 'logical_date' instead.
[2025-07-27T19:44:56.367+0000] {drift_monitoring.py:52} INFO - Execution date: 2025-07-27 18:00:00+00:00
[2025-07-27T19:44:56.367+0000] {drift_monitoring.py:60} INFO - üîç T√©l√©chargement de features/date=2025-07-27/hour=18/features.parquet et targets/date=2025-07-27/hour=18/target.parquet
[2025-07-27T19:44:56.613+0000] {taskinstance.py:441} INFO - ::group::Post task execution logs
[2025-07-27T19:44:56.615+0000] {taskinstance.py:2890} ERROR - Task failed with exception
Traceback (most recent call last):
  File "/home/airflow/.local/lib/python3.12/site-packages/airflow/models/taskinstance.py", line 465, in _execute_task
    result = _execute_callable(context=context, **execute_callable_kwargs)
             ^^^^^^^^^^^^^^^^^^^^^^^^^^^^^^^^^^^^^^^^^^^^^^^^^^^^^^^^^^^^^
  File "/home/airflow/.local/lib/python3.12/site-packages/airflow/models/taskinstance.py", line 432, in _execute_callable
    return execute_callable(context=context, **execute_callable_kwargs)
           ^^^^^^^^^^^^^^^^^^^^^^^^^^^^^^^^^^^^^^^^^^^^^^^^^^^^^^^^^^^^
  File "/home/airflow/.local/lib/python3.12/site-packages/airflow/models/baseoperator.py", line 400, in wrapper
    return func(self, *args, **kwargs)
           ^^^^^^^^^^^^^^^^^^^^^^^^^^^
  File "/home/airflow/.local/lib/python3.12/site-packages/airflow/operators/python.py", line 235, in execute
    return_value = self.execute_callable()
                   ^^^^^^^^^^^^^^^^^^^^^^^
  File "/home/airflow/.local/lib/python3.12/site-packages/airflow/operators/python.py", line 252, in execute_callable
    return self.python_callable(*self.op_args, **self.op_kwargs)
           ^^^^^^^^^^^^^^^^^^^^^^^^^^^^^^^^^^^^^^^^^^^^^^^^^^^^^
  File "/opt/airflow/dags/drift_monitoring.py", line 66, in check_drift
    obj_target = s3_client.get_object(Bucket=BUCKET_NAME, Key=key_target)
                 ^^^^^^^^^^^^^^^^^^^^^^^^^^^^^^^^^^^^^^^^^^^^^^^^^^^^^^^^
  File "/home/airflow/.local/lib/python3.12/site-packages/botocore/client.py", line 569, in _api_call
    return self._make_api_call(operation_name, kwargs)
           ^^^^^^^^^^^^^^^^^^^^^^^^^^^^^^^^^^^^^^^^^^^
  File "/home/airflow/.local/lib/python3.12/site-packages/botocore/client.py", line 1023, in _make_api_call
    raise error_class(parsed_response, operation_name)
botocore.errorfactory.NoSuchKey: An error occurred (NoSuchKey) when calling the GetObject operation: The specified key does not exist.
[2025-07-27T19:44:56.642+0000] {taskinstance.py:1205} INFO - Marking task as FAILED. dag_id=data_drift_monitoring, task_id=check_drift, execution_date=20250727T180000, start_date=20250727T194456, end_date=20250727T194456
[2025-07-27T19:44:56.668+0000] {logging_mixin.py:188} WARNING - /home/***/.local/lib/python3.12/site-packages/***/utils/email.py:154 RemovedInAirflow3Warning: Fetching SMTP credentials from configuration variables will be deprecated in a future release. Please set credentials using a connection instead.
[2025-07-27T19:44:56.669+0000] {configuration.py:1050} WARNING - section/key [smtp/smtp_user] not found in config
[2025-07-27T19:44:56.670+0000] {email.py:271} INFO - Email alerting: attempt 1
[2025-07-27T19:44:56.682+0000] {configuration.py:1050} WARNING - section/key [smtp/smtp_user] not found in config
[2025-07-27T19:44:56.683+0000] {email.py:271} INFO - Email alerting: attempt 1
[2025-07-27T19:44:56.684+0000] {taskinstance.py:879} ERROR - Failed to send email to: ['salima.mamma25@gmail.com']
Traceback (most recent call last):
  File "/home/airflow/.local/lib/python3.12/site-packages/airflow/models/taskinstance.py", line 2476, in _run_raw_task
    self._execute_task_with_callbacks(context, test_mode, session=session)
  File "/home/airflow/.local/lib/python3.12/site-packages/airflow/models/taskinstance.py", line 2663, in _execute_task_with_callbacks
    result = self._execute_task(context, task_orig)
             ^^^^^^^^^^^^^^^^^^^^^^^^^^^^^^^^^^^^^^
  File "/home/airflow/.local/lib/python3.12/site-packages/airflow/models/taskinstance.py", line 2686, in _execute_task
    return _execute_task(self, context, task_orig)
           ^^^^^^^^^^^^^^^^^^^^^^^^^^^^^^^^^^^^^^^
  File "/home/airflow/.local/lib/python3.12/site-packages/airflow/models/taskinstance.py", line 465, in _execute_task
    result = _execute_callable(context=context, **execute_callable_kwargs)
             ^^^^^^^^^^^^^^^^^^^^^^^^^^^^^^^^^^^^^^^^^^^^^^^^^^^^^^^^^^^^^
  File "/home/airflow/.local/lib/python3.12/site-packages/airflow/models/taskinstance.py", line 432, in _execute_callable
    return execute_callable(context=context, **execute_callable_kwargs)
           ^^^^^^^^^^^^^^^^^^^^^^^^^^^^^^^^^^^^^^^^^^^^^^^^^^^^^^^^^^^^
  File "/home/airflow/.local/lib/python3.12/site-packages/airflow/models/baseoperator.py", line 400, in wrapper
    return func(self, *args, **kwargs)
           ^^^^^^^^^^^^^^^^^^^^^^^^^^^
  File "/home/airflow/.local/lib/python3.12/site-packages/airflow/operators/python.py", line 235, in execute
    return_value = self.execute_callable()
                   ^^^^^^^^^^^^^^^^^^^^^^^
  File "/home/airflow/.local/lib/python3.12/site-packages/airflow/operators/python.py", line 252, in execute_callable
    return self.python_callable(*self.op_args, **self.op_kwargs)
           ^^^^^^^^^^^^^^^^^^^^^^^^^^^^^^^^^^^^^^^^^^^^^^^^^^^^^
  File "/opt/airflow/dags/drift_monitoring.py", line 66, in check_drift
    obj_target = s3_client.get_object(Bucket=BUCKET_NAME, Key=key_target)
                 ^^^^^^^^^^^^^^^^^^^^^^^^^^^^^^^^^^^^^^^^^^^^^^^^^^^^^^^^
  File "/home/airflow/.local/lib/python3.12/site-packages/botocore/client.py", line 569, in _api_call
    return self._make_api_call(operation_name, kwargs)
           ^^^^^^^^^^^^^^^^^^^^^^^^^^^^^^^^^^^^^^^^^^^
  File "/home/airflow/.local/lib/python3.12/site-packages/botocore/client.py", line 1023, in _make_api_call
    raise error_class(parsed_response, operation_name)
botocore.errorfactory.NoSuchKey: An error occurred (NoSuchKey) when calling the GetObject operation: The specified key does not exist.

During handling of the above exception, another exception occurred:

Traceback (most recent call last):
  File "/home/airflow/.local/lib/python3.12/site-packages/airflow/models/taskinstance.py", line 1063, in _email_alert
    send_email(task.email, subject, html_content)
  File "/home/airflow/.local/lib/python3.12/site-packages/airflow/utils/email.py", line 80, in send_email
    return backend(
           ^^^^^^^^
  File "/home/airflow/.local/lib/python3.12/site-packages/airflow/utils/email.py", line 154, in send_email_smtp
    send_mime_email(e_from=mail_from, e_to=recipients, mime_msg=msg, conn_id=conn_id, dryrun=dryrun)
  File "/home/airflow/.local/lib/python3.12/site-packages/airflow/utils/email.py", line 273, in send_mime_email
    smtp_conn = _get_smtp_connection(smtp_host, smtp_port, smtp_timeout, smtp_ssl)
                ^^^^^^^^^^^^^^^^^^^^^^^^^^^^^^^^^^^^^^^^^^^^^^^^^^^^^^^^^^^^^^^^^^
  File "/home/airflow/.local/lib/python3.12/site-packages/airflow/utils/email.py", line 317, in _get_smtp_connection
    return smtplib.SMTP(host=host, port=port, timeout=timeout)
           ^^^^^^^^^^^^^^^^^^^^^^^^^^^^^^^^^^^^^^^^^^^^^^^^^^^
  File "/usr/local/lib/python3.12/smtplib.py", line 255, in __init__
    (code, msg) = self.connect(host, port)
                  ^^^^^^^^^^^^^^^^^^^^^^^^
  File "/usr/local/lib/python3.12/smtplib.py", line 341, in connect
    self.sock = self._get_socket(host, port, self.timeout)
                ^^^^^^^^^^^^^^^^^^^^^^^^^^^^^^^^^^^^^^^^^^
  File "/usr/local/lib/python3.12/smtplib.py", line 312, in _get_socket
    return socket.create_connection((host, port), timeout,
           ^^^^^^^^^^^^^^^^^^^^^^^^^^^^^^^^^^^^^^^^^^^^^^^
  File "/usr/local/lib/python3.12/socket.py", line 852, in create_connection
    raise exceptions[0]
  File "/usr/local/lib/python3.12/socket.py", line 837, in create_connection
    sock.connect(sa)
ConnectionRefusedError: [Errno 111] Connection refused

During handling of the above exception, another exception occurred:

Traceback (most recent call last):
  File "/home/airflow/.local/lib/python3.12/site-packages/airflow/models/taskinstance.py", line 877, in _handle_failure
    task_instance.email_alert(error, failure_context["task"])
  File "/home/airflow/.local/lib/python3.12/site-packages/airflow/models/taskinstance.py", line 3148, in email_alert
    _email_alert(task_instance=self, exception=exception, task=task)
  File "/home/airflow/.local/lib/python3.12/site-packages/airflow/models/taskinstance.py", line 1065, in _email_alert
    send_email(task.email, subject, html_content_err)
  File "/home/airflow/.local/lib/python3.12/site-packages/airflow/utils/email.py", line 80, in send_email
    return backend(
           ^^^^^^^^
  File "/home/airflow/.local/lib/python3.12/site-packages/airflow/utils/email.py", line 154, in send_email_smtp
    send_mime_email(e_from=mail_from, e_to=recipients, mime_msg=msg, conn_id=conn_id, dryrun=dryrun)
  File "/home/airflow/.local/lib/python3.12/site-packages/airflow/utils/email.py", line 273, in send_mime_email
    smtp_conn = _get_smtp_connection(smtp_host, smtp_port, smtp_timeout, smtp_ssl)
                ^^^^^^^^^^^^^^^^^^^^^^^^^^^^^^^^^^^^^^^^^^^^^^^^^^^^^^^^^^^^^^^^^^
  File "/home/airflow/.local/lib/python3.12/site-packages/airflow/utils/email.py", line 317, in _get_smtp_connection
    return smtplib.SMTP(host=host, port=port, timeout=timeout)
           ^^^^^^^^^^^^^^^^^^^^^^^^^^^^^^^^^^^^^^^^^^^^^^^^^^^
  File "/usr/local/lib/python3.12/smtplib.py", line 255, in __init__
    (code, msg) = self.connect(host, port)
                  ^^^^^^^^^^^^^^^^^^^^^^^^
  File "/usr/local/lib/python3.12/smtplib.py", line 341, in connect
    self.sock = self._get_socket(host, port, self.timeout)
                ^^^^^^^^^^^^^^^^^^^^^^^^^^^^^^^^^^^^^^^^^^
  File "/usr/local/lib/python3.12/smtplib.py", line 312, in _get_socket
    return socket.create_connection((host, port), timeout,
           ^^^^^^^^^^^^^^^^^^^^^^^^^^^^^^^^^^^^^^^^^^^^^^^
  File "/usr/local/lib/python3.12/socket.py", line 852, in create_connection
    raise exceptions[0]
  File "/usr/local/lib/python3.12/socket.py", line 837, in create_connection
    sock.connect(sa)
ConnectionRefusedError: [Errno 111] Connection refused
[2025-07-27T19:44:56.745+0000] {standard_task_runner.py:110} ERROR - Failed to execute job 9 for task check_drift (An error occurred (NoSuchKey) when calling the GetObject operation: The specified key does not exist.; 881)
[2025-07-27T19:44:56.778+0000] {local_task_job_runner.py:240} INFO - Task exited with return code 1
[2025-07-27T19:44:56.804+0000] {taskinstance.py:3482} INFO - 0 downstream tasks scheduled from follow-on schedule check
[2025-07-27T19:44:56.807+0000] {local_task_job_runner.py:222} INFO - ::endgroup::
[2025-07-27T19:51:58.583+0000] {local_task_job_runner.py:120} INFO - ::group::Pre task execution logs
[2025-07-27T19:51:58.624+0000] {taskinstance.py:2073} INFO - Dependencies all met for dep_context=non-requeueable deps ti=<TaskInstance: data_drift_monitoring.check_drift scheduled__2025-07-27T18:00:00+00:00 [queued]>
[2025-07-27T19:51:58.634+0000] {taskinstance.py:2073} INFO - Dependencies all met for dep_context=requeueable deps ti=<TaskInstance: data_drift_monitoring.check_drift scheduled__2025-07-27T18:00:00+00:00 [queued]>
[2025-07-27T19:51:58.635+0000] {taskinstance.py:2303} INFO - Starting attempt 1 of 1
[2025-07-27T19:51:58.687+0000] {taskinstance.py:2327} INFO - Executing <Task(PythonOperator): check_drift> on 2025-07-27 18:00:00+00:00
[2025-07-27T19:51:58.703+0000] {standard_task_runner.py:90} INFO - Running: ['***', 'tasks', 'run', 'data_drift_monitoring', 'check_drift', 'scheduled__2025-07-27T18:00:00+00:00', '--job-id', '9', '--raw', '--subdir', 'DAGS_FOLDER/drift_monitoring.py', '--cfg-path', '/tmp/tmppnbrxa6k']
[2025-07-27T19:51:58.704+0000] {logging_mixin.py:188} WARNING - /home/***/.local/lib/python3.12/site-packages/***/task/task_runner/standard_task_runner.py:61 DeprecationWarning: This process (pid=759) is multi-threaded, use of fork() may lead to deadlocks in the child.
[2025-07-27T19:51:58.707+0000] {standard_task_runner.py:91} INFO - Job 9: Subtask check_drift
[2025-07-27T19:51:58.707+0000] {standard_task_runner.py:63} INFO - Started process 761 to run task
[2025-07-27T19:51:58.732+0000] {logging_mixin.py:188} WARNING - /home/***/.local/lib/python3.12/site-packages/***/settings.py:195 DeprecationWarning: The sql_alchemy_conn option in [core] has been moved to the sql_alchemy_conn option in [database] - the old setting has been used, but please update your config.
[2025-07-27T19:51:58.783+0000] {task_command.py:426} INFO - Running <TaskInstance: data_drift_monitoring.check_drift scheduled__2025-07-27T18:00:00+00:00 [running]> on host ad1b488300d1
[2025-07-27T19:51:58.967+0000] {taskinstance.py:2644} INFO - Exporting env vars: AIRFLOW_CTX_DAG_OWNER='mlops' AIRFLOW_CTX_DAG_ID='data_drift_monitoring' AIRFLOW_CTX_TASK_ID='check_drift' AIRFLOW_CTX_EXECUTION_DATE='2025-07-27T18:00:00+00:00' AIRFLOW_CTX_TRY_NUMBER='1' AIRFLOW_CTX_DAG_RUN_ID='scheduled__2025-07-27T18:00:00+00:00'
[2025-07-27T19:51:58.969+0000] {taskinstance.py:430} INFO - ::endgroup::
[2025-07-27T19:51:58.985+0000] {logging_mixin.py:188} WARNING - /home/***/.local/lib/python3.12/site-packages/***/utils/context.py:320 AirflowContextDeprecationWarning: Accessing 'execution_date' from the template is deprecated and will be removed in a future version. Please use 'data_interval_start' or 'logical_date' instead.
[2025-07-27T19:51:58.986+0000] {drift_monitoring.py:50} INFO - Execution date: 2025-07-27 18:00:00+00:00
[2025-07-27T19:51:58.987+0000] {drift_monitoring.py:58} INFO - üîç T√©l√©chargement de features/date=2025-07-27/hour=18/features.parquet et targets/date=2025-07-27/hour=18/target.parquet
[2025-07-27T19:51:59.155+0000] {taskinstance.py:441} INFO - ::group::Post task execution logs
[2025-07-27T19:51:59.156+0000] {taskinstance.py:2890} ERROR - Task failed with exception
Traceback (most recent call last):
  File "/home/airflow/.local/lib/python3.12/site-packages/airflow/models/taskinstance.py", line 465, in _execute_task
    result = _execute_callable(context=context, **execute_callable_kwargs)
             ^^^^^^^^^^^^^^^^^^^^^^^^^^^^^^^^^^^^^^^^^^^^^^^^^^^^^^^^^^^^^
  File "/home/airflow/.local/lib/python3.12/site-packages/airflow/models/taskinstance.py", line 432, in _execute_callable
    return execute_callable(context=context, **execute_callable_kwargs)
           ^^^^^^^^^^^^^^^^^^^^^^^^^^^^^^^^^^^^^^^^^^^^^^^^^^^^^^^^^^^^
  File "/home/airflow/.local/lib/python3.12/site-packages/airflow/models/baseoperator.py", line 400, in wrapper
    return func(self, *args, **kwargs)
           ^^^^^^^^^^^^^^^^^^^^^^^^^^^
  File "/home/airflow/.local/lib/python3.12/site-packages/airflow/operators/python.py", line 235, in execute
    return_value = self.execute_callable()
                   ^^^^^^^^^^^^^^^^^^^^^^^
  File "/home/airflow/.local/lib/python3.12/site-packages/airflow/operators/python.py", line 252, in execute_callable
    return self.python_callable(*self.op_args, **self.op_kwargs)
           ^^^^^^^^^^^^^^^^^^^^^^^^^^^^^^^^^^^^^^^^^^^^^^^^^^^^^
  File "/opt/airflow/dags/drift_monitoring.py", line 64, in check_drift
    obj_target = s3_client.get_object(Bucket=BUCKET_NAME, Key=key_target)
                 ^^^^^^^^^^^^^^^^^^^^^^^^^^^^^^^^^^^^^^^^^^^^^^^^^^^^^^^^
  File "/home/airflow/.local/lib/python3.12/site-packages/botocore/client.py", line 569, in _api_call
    return self._make_api_call(operation_name, kwargs)
           ^^^^^^^^^^^^^^^^^^^^^^^^^^^^^^^^^^^^^^^^^^^
  File "/home/airflow/.local/lib/python3.12/site-packages/botocore/client.py", line 1023, in _make_api_call
    raise error_class(parsed_response, operation_name)
botocore.errorfactory.NoSuchKey: An error occurred (NoSuchKey) when calling the GetObject operation: The specified key does not exist.
[2025-07-27T19:51:59.175+0000] {taskinstance.py:1205} INFO - Marking task as FAILED. dag_id=data_drift_monitoring, task_id=check_drift, execution_date=20250727T180000, start_date=20250727T195158, end_date=20250727T195159
[2025-07-27T19:51:59.195+0000] {standard_task_runner.py:110} ERROR - Failed to execute job 9 for task check_drift (An error occurred (NoSuchKey) when calling the GetObject operation: The specified key does not exist.; 761)
[2025-07-27T19:51:59.256+0000] {local_task_job_runner.py:240} INFO - Task exited with return code 1
[2025-07-27T19:51:59.281+0000] {taskinstance.py:3482} INFO - 0 downstream tasks scheduled from follow-on schedule check
[2025-07-27T19:51:59.318+0000] {local_task_job_runner.py:222} INFO - ::endgroup::
