[2025-07-27T22:31:36.994+0000] {local_task_job_runner.py:120} INFO - ::group::Pre task execution logs
[2025-07-27T22:31:37.033+0000] {taskinstance.py:2073} INFO - Dependencies all met for dep_context=non-requeueable deps ti=<TaskInstance: weekly_monitoring.aggregate_predictions manual__2025-07-27T22:31:34.056100+00:00 [queued]>
[2025-07-27T22:31:37.043+0000] {taskinstance.py:2073} INFO - Dependencies all met for dep_context=requeueable deps ti=<TaskInstance: weekly_monitoring.aggregate_predictions manual__2025-07-27T22:31:34.056100+00:00 [queued]>
[2025-07-27T22:31:37.044+0000] {taskinstance.py:2303} INFO - Starting attempt 1 of 2
[2025-07-27T22:31:37.056+0000] {taskinstance.py:2327} INFO - Executing <Task(PythonOperator): aggregate_predictions> on 2025-07-27 22:31:34.056100+00:00
[2025-07-27T22:31:37.073+0000] {logging_mixin.py:188} WARNING - /home/***/.local/lib/python3.12/site-packages/***/task/task_runner/standard_task_runner.py:61 DeprecationWarning: This process (pid=303) is multi-threaded, use of fork() may lead to deadlocks in the child.
[2025-07-27T22:31:37.070+0000] {standard_task_runner.py:90} INFO - Running: ['***', 'tasks', 'run', 'weekly_monitoring', 'aggregate_predictions', 'manual__2025-07-27T22:31:34.056100+00:00', '--job-id', '2', '--raw', '--subdir', 'DAGS_FOLDER/daily_monitoring.py', '--cfg-path', '/tmp/tmp09vqatet']
[2025-07-27T22:31:37.074+0000] {standard_task_runner.py:63} INFO - Started process 339 to run task
[2025-07-27T22:31:37.074+0000] {standard_task_runner.py:91} INFO - Job 2: Subtask aggregate_predictions
[2025-07-27T22:31:37.092+0000] {logging_mixin.py:188} WARNING - /home/***/.local/lib/python3.12/site-packages/***/settings.py:195 DeprecationWarning: The sql_alchemy_conn option in [core] has been moved to the sql_alchemy_conn option in [database] - the old setting has been used, but please update your config.
[2025-07-27T22:31:37.131+0000] {task_command.py:426} INFO - Running <TaskInstance: weekly_monitoring.aggregate_predictions manual__2025-07-27T22:31:34.056100+00:00 [running]> on host c6592edc720c
[2025-07-27T22:31:37.224+0000] {taskinstance.py:2644} INFO - Exporting env vars: AIRFLOW_CTX_DAG_OWNER='mlops' AIRFLOW_CTX_DAG_ID='weekly_monitoring' AIRFLOW_CTX_TASK_ID='aggregate_predictions' AIRFLOW_CTX_EXECUTION_DATE='2025-07-27T22:31:34.056100+00:00' AIRFLOW_CTX_TRY_NUMBER='1' AIRFLOW_CTX_DAG_RUN_ID='manual__2025-07-27T22:31:34.056100+00:00'
[2025-07-27T22:31:37.226+0000] {taskinstance.py:430} INFO - ::endgroup::
[2025-07-27T22:31:37.296+0000] {taskinstance.py:441} INFO - ::group::Post task execution logs
[2025-07-27T22:31:37.297+0000] {taskinstance.py:2890} ERROR - Task failed with exception
Traceback (most recent call last):
  File "/home/airflow/.local/lib/python3.12/site-packages/airflow/models/taskinstance.py", line 465, in _execute_task
    result = _execute_callable(context=context, **execute_callable_kwargs)
             ^^^^^^^^^^^^^^^^^^^^^^^^^^^^^^^^^^^^^^^^^^^^^^^^^^^^^^^^^^^^^
  File "/home/airflow/.local/lib/python3.12/site-packages/airflow/models/taskinstance.py", line 432, in _execute_callable
    return execute_callable(context=context, **execute_callable_kwargs)
           ^^^^^^^^^^^^^^^^^^^^^^^^^^^^^^^^^^^^^^^^^^^^^^^^^^^^^^^^^^^^
  File "/home/airflow/.local/lib/python3.12/site-packages/airflow/models/baseoperator.py", line 400, in wrapper
    return func(self, *args, **kwargs)
           ^^^^^^^^^^^^^^^^^^^^^^^^^^^
  File "/home/airflow/.local/lib/python3.12/site-packages/airflow/operators/python.py", line 235, in execute
    return_value = self.execute_callable()
                   ^^^^^^^^^^^^^^^^^^^^^^^
  File "/home/airflow/.local/lib/python3.12/site-packages/airflow/operators/python.py", line 252, in execute_callable
    return self.python_callable(*self.op_args, **self.op_kwargs)
           ^^^^^^^^^^^^^^^^^^^^^^^^^^^^^^^^^^^^^^^^^^^^^^^^^^^^^
  File "/opt/airflow/dags/daily_monitoring.py", line 65, in aggregate_predictions
    obj = s3_client.get_object(Bucket=S3_BUCKET, Key=key)
          ^^^^^^^^^^^^^^^^^^^^^^^^^^^^^^^^^^^^^^^^^^^^^^^
  File "/home/airflow/.local/lib/python3.12/site-packages/botocore/client.py", line 569, in _api_call
    return self._make_api_call(operation_name, kwargs)
           ^^^^^^^^^^^^^^^^^^^^^^^^^^^^^^^^^^^^^^^^^^^
  File "/home/airflow/.local/lib/python3.12/site-packages/botocore/client.py", line 1023, in _make_api_call
    raise error_class(parsed_response, operation_name)
botocore.errorfactory.NoSuchBucket: An error occurred (NoSuchBucket) when calling the GetObject operation: The specified bucket does not exist
[2025-07-27T22:31:37.316+0000] {taskinstance.py:1205} INFO - Marking task as UP_FOR_RETRY. dag_id=weekly_monitoring, task_id=aggregate_predictions, execution_date=20250727T223134, start_date=20250727T223137, end_date=20250727T223137
[2025-07-27T22:31:37.336+0000] {standard_task_runner.py:110} ERROR - Failed to execute job 2 for task aggregate_predictions (An error occurred (NoSuchBucket) when calling the GetObject operation: The specified bucket does not exist; 339)
[2025-07-27T22:31:37.368+0000] {local_task_job_runner.py:240} INFO - Task exited with return code 1
[2025-07-27T22:31:37.390+0000] {taskinstance.py:3482} INFO - 0 downstream tasks scheduled from follow-on schedule check
[2025-07-27T22:31:37.393+0000] {local_task_job_runner.py:222} INFO - ::endgroup::
