[2025-07-31T13:16:34.141+0000] {local_task_job_runner.py:120} INFO - ::group::Pre task execution logs
[2025-07-31T13:16:34.195+0000] {taskinstance.py:2073} INFO - Dependencies all met for dep_context=non-requeueable deps ti=<TaskInstance: monitoring_pipeline.generate_evidently_report manual__2025-07-31T13:16:26.460418+00:00 [queued]>
[2025-07-31T13:16:34.208+0000] {taskinstance.py:2073} INFO - Dependencies all met for dep_context=requeueable deps ti=<TaskInstance: monitoring_pipeline.generate_evidently_report manual__2025-07-31T13:16:26.460418+00:00 [queued]>
[2025-07-31T13:16:34.240+0000] {taskinstance.py:2303} INFO - Starting attempt 1 of 2
[2025-07-31T13:16:34.261+0000] {taskinstance.py:2327} INFO - Executing <Task(PythonOperator): generate_evidently_report> on 2025-07-31 13:16:26.460418+00:00
[2025-07-31T13:16:34.287+0000] {logging_mixin.py:188} WARNING - /home/***/.local/lib/python3.12/site-packages/***/task/task_runner/standard_task_runner.py:61 DeprecationWarning: This process (pid=3215) is multi-threaded, use of fork() may lead to deadlocks in the child.
[2025-07-31T13:16:34.286+0000] {standard_task_runner.py:90} INFO - Running: ['***', 'tasks', 'run', 'monitoring_pipeline', 'generate_evidently_report', 'manual__2025-07-31T13:16:26.460418+00:00', '--job-id', '201', '--raw', '--subdir', 'DAGS_FOLDER/drift_monitoring.py', '--cfg-path', '/tmp/tmp723lc26o']
[2025-07-31T13:16:34.290+0000] {standard_task_runner.py:63} INFO - Started process 3251 to run task
[2025-07-31T13:16:34.290+0000] {standard_task_runner.py:91} INFO - Job 201: Subtask generate_evidently_report
[2025-07-31T13:16:34.347+0000] {logging_mixin.py:188} WARNING - /home/***/.local/lib/python3.12/site-packages/***/settings.py:195 DeprecationWarning: The sql_alchemy_conn option in [core] has been moved to the sql_alchemy_conn option in [database] - the old setting has been used, but please update your config.
[2025-07-31T13:16:34.407+0000] {task_command.py:426} INFO - Running <TaskInstance: monitoring_pipeline.generate_evidently_report manual__2025-07-31T13:16:26.460418+00:00 [running]> on host 44c57df83f33
[2025-07-31T13:16:34.598+0000] {taskinstance.py:2644} INFO - Exporting env vars: AIRFLOW_CTX_DAG_OWNER='mlops' AIRFLOW_CTX_DAG_ID='monitoring_pipeline' AIRFLOW_CTX_TASK_ID='generate_evidently_report' AIRFLOW_CTX_EXECUTION_DATE='2025-07-31T13:16:26.460418+00:00' AIRFLOW_CTX_TRY_NUMBER='1' AIRFLOW_CTX_DAG_RUN_ID='manual__2025-07-31T13:16:26.460418+00:00'
[2025-07-31T13:16:34.600+0000] {taskinstance.py:430} INFO - ::endgroup::
[2025-07-31T13:16:34.652+0000] {taskinstance.py:441} INFO - ::group::Post task execution logs
[2025-07-31T13:16:34.654+0000] {taskinstance.py:2890} ERROR - Task failed with exception
Traceback (most recent call last):
  File "/home/airflow/.local/lib/python3.12/site-packages/airflow/models/taskinstance.py", line 465, in _execute_task
    result = _execute_callable(context=context, **execute_callable_kwargs)
             ^^^^^^^^^^^^^^^^^^^^^^^^^^^^^^^^^^^^^^^^^^^^^^^^^^^^^^^^^^^^^
  File "/home/airflow/.local/lib/python3.12/site-packages/airflow/models/taskinstance.py", line 432, in _execute_callable
    return execute_callable(context=context, **execute_callable_kwargs)
           ^^^^^^^^^^^^^^^^^^^^^^^^^^^^^^^^^^^^^^^^^^^^^^^^^^^^^^^^^^^^
  File "/home/airflow/.local/lib/python3.12/site-packages/airflow/models/baseoperator.py", line 400, in wrapper
    return func(self, *args, **kwargs)
           ^^^^^^^^^^^^^^^^^^^^^^^^^^^
  File "/home/airflow/.local/lib/python3.12/site-packages/airflow/operators/python.py", line 235, in execute
    return_value = self.execute_callable()
                   ^^^^^^^^^^^^^^^^^^^^^^^
  File "/home/airflow/.local/lib/python3.12/site-packages/airflow/operators/python.py", line 252, in execute_callable
    return self.python_callable(*self.op_args, **self.op_kwargs)
           ^^^^^^^^^^^^^^^^^^^^^^^^^^^^^^^^^^^^^^^^^^^^^^^^^^^^^
  File "/opt/airflow/dags/drift_monitoring.py", line 81, in generate_evidently_report
    df_features = load_data_from_s3("features", days=7)
                  ^^^^^^^^^^^^^^^^^^^^^^^^^^^^^^^^^^^^^
  File "/opt/airflow/dags/drift_monitoring.py", line 65, in load_data_from_s3
    obj = s3_client.get_object(Bucket=BUCKET_NAME, Key=key)
          ^^^^^^^^^^^^^^^^^^^^^^^^^^^^^^^^^^^^^^^^^^^^^^^^^
  File "/home/airflow/.local/lib/python3.12/site-packages/botocore/client.py", line 569, in _api_call
    return self._make_api_call(operation_name, kwargs)
           ^^^^^^^^^^^^^^^^^^^^^^^^^^^^^^^^^^^^^^^^^^^
  File "/home/airflow/.local/lib/python3.12/site-packages/botocore/client.py", line 1023, in _make_api_call
    raise error_class(parsed_response, operation_name)
botocore.errorfactory.NoSuchBucket: An error occurred (NoSuchBucket) when calling the GetObject operation: The specified bucket does not exist
[2025-07-31T13:16:34.678+0000] {taskinstance.py:1205} INFO - Marking task as UP_FOR_RETRY. dag_id=monitoring_pipeline, task_id=generate_evidently_report, execution_date=20250731T131626, start_date=20250731T131634, end_date=20250731T131634
[2025-07-31T13:16:34.697+0000] {standard_task_runner.py:110} ERROR - Failed to execute job 201 for task generate_evidently_report (An error occurred (NoSuchBucket) when calling the GetObject operation: The specified bucket does not exist; 3251)
[2025-07-31T13:16:34.747+0000] {local_task_job_runner.py:240} INFO - Task exited with return code 1
[2025-07-31T13:16:34.782+0000] {taskinstance.py:3482} INFO - 0 downstream tasks scheduled from follow-on schedule check
[2025-07-31T13:16:34.786+0000] {local_task_job_runner.py:222} INFO - ::endgroup::
