[2025-07-31T15:23:05.906+0000] {local_task_job_runner.py:120} INFO - ::group::Pre task execution logs
[2025-07-31T15:23:05.957+0000] {taskinstance.py:2073} INFO - Dependencies all met for dep_context=non-requeueable deps ti=<TaskInstance: drift_monitoring_dag.check_drift_and_trigger scheduled__2025-07-31T14:00:00+00:00 [queued]>
[2025-07-31T15:23:05.974+0000] {taskinstance.py:2073} INFO - Dependencies all met for dep_context=requeueable deps ti=<TaskInstance: drift_monitoring_dag.check_drift_and_trigger scheduled__2025-07-31T14:00:00+00:00 [queued]>
[2025-07-31T15:23:06.005+0000] {taskinstance.py:2303} INFO - Starting attempt 1 of 2
[2025-07-31T15:23:06.029+0000] {taskinstance.py:2327} INFO - Executing <Task(PythonOperator): check_drift_and_trigger> on 2025-07-31 14:00:00+00:00
[2025-07-31T15:23:06.051+0000] {standard_task_runner.py:90} INFO - Running: ['***', 'tasks', 'run', 'drift_monitoring_dag', 'check_drift_and_trigger', 'scheduled__2025-07-31T14:00:00+00:00', '--job-id', '218', '--raw', '--subdir', 'DAGS_FOLDER/drift_monitoring.py', '--cfg-path', '/tmp/tmpj_t5yagp']
[2025-07-31T15:23:06.055+0000] {standard_task_runner.py:91} INFO - Job 218: Subtask check_drift_and_trigger
[2025-07-31T15:23:06.060+0000] {logging_mixin.py:188} WARNING - /home/***/.local/lib/python3.12/site-packages/***/task/task_runner/standard_task_runner.py:61 DeprecationWarning: This process (pid=8339) is multi-threaded, use of fork() may lead to deadlocks in the child.
[2025-07-31T15:23:06.063+0000] {standard_task_runner.py:63} INFO - Started process 8416 to run task
[2025-07-31T15:23:06.114+0000] {logging_mixin.py:188} WARNING - /home/***/.local/lib/python3.12/site-packages/***/settings.py:195 DeprecationWarning: The sql_alchemy_conn option in [core] has been moved to the sql_alchemy_conn option in [database] - the old setting has been used, but please update your config.
[2025-07-31T15:23:06.169+0000] {task_command.py:426} INFO - Running <TaskInstance: drift_monitoring_dag.check_drift_and_trigger scheduled__2025-07-31T14:00:00+00:00 [running]> on host 44c57df83f33
[2025-07-31T15:23:06.354+0000] {taskinstance.py:2644} INFO - Exporting env vars: AIRFLOW_CTX_DAG_OWNER='***' AIRFLOW_CTX_DAG_ID='drift_monitoring_dag' AIRFLOW_CTX_TASK_ID='check_drift_and_trigger' AIRFLOW_CTX_EXECUTION_DATE='2025-07-31T14:00:00+00:00' AIRFLOW_CTX_TRY_NUMBER='1' AIRFLOW_CTX_DAG_RUN_ID='scheduled__2025-07-31T14:00:00+00:00'
[2025-07-31T15:23:06.357+0000] {taskinstance.py:430} INFO - ::endgroup::
[2025-07-31T15:23:06.414+0000] {drift_monitoring.py:62} WARNING - File not found: s3://crypto-mlops-bucket/predictions/date=2025-07-31/hour=15/prediction.parquet
[2025-07-31T15:23:06.428+0000] {drift_monitoring.py:62} WARNING - File not found: s3://crypto-mlops-bucket/targets/date=2025-07-31/hour=15/target.parquet
[2025-07-31T15:23:06.491+0000] {drift_monitoring.py:62} WARNING - File not found: s3://crypto-mlops-bucket/targets/date=2025-07-31/hour=14/target.parquet
[2025-07-31T15:23:06.527+0000] {taskinstance.py:441} INFO - ::group::Post task execution logs
[2025-07-31T15:23:06.529+0000] {taskinstance.py:2890} ERROR - Task failed with exception
Traceback (most recent call last):
  File "/home/airflow/.local/lib/python3.12/site-packages/airflow/models/taskinstance.py", line 465, in _execute_task
    result = _execute_callable(context=context, **execute_callable_kwargs)
             ^^^^^^^^^^^^^^^^^^^^^^^^^^^^^^^^^^^^^^^^^^^^^^^^^^^^^^^^^^^^^
  File "/home/airflow/.local/lib/python3.12/site-packages/airflow/models/taskinstance.py", line 432, in _execute_callable
    return execute_callable(context=context, **execute_callable_kwargs)
           ^^^^^^^^^^^^^^^^^^^^^^^^^^^^^^^^^^^^^^^^^^^^^^^^^^^^^^^^^^^^
  File "/home/airflow/.local/lib/python3.12/site-packages/airflow/models/baseoperator.py", line 400, in wrapper
    return func(self, *args, **kwargs)
           ^^^^^^^^^^^^^^^^^^^^^^^^^^^
  File "/home/airflow/.local/lib/python3.12/site-packages/airflow/operators/python.py", line 235, in execute
    return_value = self.execute_callable()
                   ^^^^^^^^^^^^^^^^^^^^^^^
  File "/home/airflow/.local/lib/python3.12/site-packages/airflow/operators/python.py", line 252, in execute_callable
    return self.python_callable(*self.op_args, **self.op_kwargs)
           ^^^^^^^^^^^^^^^^^^^^^^^^^^^^^^^^^^^^^^^^^^^^^^^^^^^^^
  File "/opt/airflow/dags/drift_monitoring.py", line 111, in check_drift_and_trigger
    merged_df = pd.merge(pred_df, target_df, on="id", how="inner")
                ^^^^^^^^^^^^^^^^^^^^^^^^^^^^^^^^^^^^^^^^^^^^^^^^^^
  File "/home/airflow/.local/lib/python3.12/site-packages/pandas/core/reshape/merge.py", line 170, in merge
    op = _MergeOperation(
         ^^^^^^^^^^^^^^^^
  File "/home/airflow/.local/lib/python3.12/site-packages/pandas/core/reshape/merge.py", line 794, in __init__
    ) = self._get_merge_keys()
        ^^^^^^^^^^^^^^^^^^^^^^
  File "/home/airflow/.local/lib/python3.12/site-packages/pandas/core/reshape/merge.py", line 1297, in _get_merge_keys
    right_keys.append(right._get_label_or_level_values(rk))
                      ^^^^^^^^^^^^^^^^^^^^^^^^^^^^^^^^^^^^
  File "/home/airflow/.local/lib/python3.12/site-packages/pandas/core/generic.py", line 1911, in _get_label_or_level_values
    raise KeyError(key)
KeyError: 'id'
[2025-07-31T15:23:06.561+0000] {taskinstance.py:1205} INFO - Marking task as UP_FOR_RETRY. dag_id=drift_monitoring_dag, task_id=check_drift_and_trigger, execution_date=20250731T140000, start_date=20250731T152305, end_date=20250731T152306
[2025-07-31T15:23:06.619+0000] {standard_task_runner.py:110} ERROR - Failed to execute job 218 for task check_drift_and_trigger ('id'; 8416)
[2025-07-31T15:23:06.681+0000] {local_task_job_runner.py:240} INFO - Task exited with return code 1
[2025-07-31T15:23:06.706+0000] {taskinstance.py:3482} INFO - 0 downstream tasks scheduled from follow-on schedule check
[2025-07-31T15:23:06.710+0000] {local_task_job_runner.py:222} INFO - ::endgroup::
