[2025-07-31T13:28:46.125+0000] {local_task_job_runner.py:120} INFO - ::group::Pre task execution logs
[2025-07-31T13:28:46.184+0000] {taskinstance.py:2073} INFO - Dependencies all met for dep_context=non-requeueable deps ti=<TaskInstance: drift_monitoring_dag.check_drift_and_trigger manual__2025-07-31T13:28:40.692034+00:00 [queued]>
[2025-07-31T13:28:46.198+0000] {taskinstance.py:2073} INFO - Dependencies all met for dep_context=requeueable deps ti=<TaskInstance: drift_monitoring_dag.check_drift_and_trigger manual__2025-07-31T13:28:40.692034+00:00 [queued]>
[2025-07-31T13:28:46.199+0000] {taskinstance.py:2303} INFO - Starting attempt 1 of 2
[2025-07-31T13:28:46.222+0000] {taskinstance.py:2327} INFO - Executing <Task(PythonOperator): check_drift_and_trigger> on 2025-07-31 13:28:40.692034+00:00
[2025-07-31T13:28:46.244+0000] {standard_task_runner.py:90} INFO - Running: ['***', 'tasks', 'run', 'drift_monitoring_dag', 'check_drift_and_trigger', 'manual__2025-07-31T13:28:40.692034+00:00', '--job-id', '206', '--raw', '--subdir', 'DAGS_FOLDER/drift_monitoring.py', '--cfg-path', '/tmp/tmpmhxf5mei']
[2025-07-31T13:28:46.250+0000] {standard_task_runner.py:91} INFO - Job 206: Subtask check_drift_and_trigger
[2025-07-31T13:28:46.257+0000] {logging_mixin.py:188} WARNING - /home/***/.local/lib/python3.12/site-packages/***/task/task_runner/standard_task_runner.py:61 DeprecationWarning: This process (pid=4692) is multi-threaded, use of fork() may lead to deadlocks in the child.
[2025-07-31T13:28:46.260+0000] {standard_task_runner.py:63} INFO - Started process 4732 to run task
[2025-07-31T13:28:46.313+0000] {logging_mixin.py:188} WARNING - /home/***/.local/lib/python3.12/site-packages/***/settings.py:195 DeprecationWarning: The sql_alchemy_conn option in [core] has been moved to the sql_alchemy_conn option in [database] - the old setting has been used, but please update your config.
[2025-07-31T13:28:46.382+0000] {task_command.py:426} INFO - Running <TaskInstance: drift_monitoring_dag.check_drift_and_trigger manual__2025-07-31T13:28:40.692034+00:00 [running]> on host 44c57df83f33
[2025-07-31T13:28:46.600+0000] {taskinstance.py:2644} INFO - Exporting env vars: AIRFLOW_CTX_DAG_OWNER='***' AIRFLOW_CTX_DAG_ID='drift_monitoring_dag' AIRFLOW_CTX_TASK_ID='check_drift_and_trigger' AIRFLOW_CTX_EXECUTION_DATE='2025-07-31T13:28:40.692034+00:00' AIRFLOW_CTX_TRY_NUMBER='1' AIRFLOW_CTX_DAG_RUN_ID='manual__2025-07-31T13:28:40.692034+00:00'
[2025-07-31T13:28:46.602+0000] {taskinstance.py:430} INFO - ::endgroup::
[2025-07-31T13:28:46.990+0000] {taskinstance.py:441} INFO - ::group::Post task execution logs
[2025-07-31T13:28:46.992+0000] {taskinstance.py:2890} ERROR - Task failed with exception
Traceback (most recent call last):
  File "/opt/airflow/dags/drift_monitoring.py", line 56, in load_parquet
    obj = s3_client.get_object(Bucket=bucket, Key=key)
          ^^^^^^^^^^^^^^^^^^^^^^^^^^^^^^^^^^^^^^^^^^^^
  File "/home/airflow/.local/lib/python3.12/site-packages/botocore/client.py", line 569, in _api_call
    return self._make_api_call(operation_name, kwargs)
           ^^^^^^^^^^^^^^^^^^^^^^^^^^^^^^^^^^^^^^^^^^^
  File "/home/airflow/.local/lib/python3.12/site-packages/botocore/client.py", line 1023, in _make_api_call
    raise error_class(parsed_response, operation_name)
botocore.errorfactory.NoSuchKey: An error occurred (NoSuchKey) when calling the GetObject operation: The specified key does not exist.

During handling of the above exception, another exception occurred:

Traceback (most recent call last):
  File "/home/airflow/.local/lib/python3.12/site-packages/airflow/models/taskinstance.py", line 465, in _execute_task
    result = _execute_callable(context=context, **execute_callable_kwargs)
             ^^^^^^^^^^^^^^^^^^^^^^^^^^^^^^^^^^^^^^^^^^^^^^^^^^^^^^^^^^^^^
  File "/home/airflow/.local/lib/python3.12/site-packages/airflow/models/taskinstance.py", line 432, in _execute_callable
    return execute_callable(context=context, **execute_callable_kwargs)
           ^^^^^^^^^^^^^^^^^^^^^^^^^^^^^^^^^^^^^^^^^^^^^^^^^^^^^^^^^^^^
  File "/home/airflow/.local/lib/python3.12/site-packages/airflow/models/baseoperator.py", line 400, in wrapper
    return func(self, *args, **kwargs)
           ^^^^^^^^^^^^^^^^^^^^^^^^^^^
  File "/home/airflow/.local/lib/python3.12/site-packages/airflow/operators/python.py", line 235, in execute
    return_value = self.execute_callable()
                   ^^^^^^^^^^^^^^^^^^^^^^^
  File "/home/airflow/.local/lib/python3.12/site-packages/airflow/operators/python.py", line 252, in execute_callable
    return self.python_callable(*self.op_args, **self.op_kwargs)
           ^^^^^^^^^^^^^^^^^^^^^^^^^^^^^^^^^^^^^^^^^^^^^^^^^^^^^
  File "/opt/airflow/dags/drift_monitoring.py", line 107, in check_drift_and_trigger
    target_df = load_parquet(BUCKET_NAME, target_key)
                ^^^^^^^^^^^^^^^^^^^^^^^^^^^^^^^^^^^^^
  File "/opt/airflow/dags/drift_monitoring.py", line 61, in load_parquet
    logger.warning(f"File not found: s3://{bucket}/{key}")
    ^^^^^^
NameError: name 'logger' is not defined
[2025-07-31T13:28:47.022+0000] {taskinstance.py:1205} INFO - Marking task as UP_FOR_RETRY. dag_id=drift_monitoring_dag, task_id=check_drift_and_trigger, execution_date=20250731T132840, start_date=20250731T132846, end_date=20250731T132847
[2025-07-31T13:28:47.048+0000] {standard_task_runner.py:110} ERROR - Failed to execute job 206 for task check_drift_and_trigger (name 'logger' is not defined; 4732)
[2025-07-31T13:28:47.098+0000] {local_task_job_runner.py:240} INFO - Task exited with return code 1
[2025-07-31T13:28:47.126+0000] {taskinstance.py:3482} INFO - 0 downstream tasks scheduled from follow-on schedule check
[2025-07-31T13:28:47.130+0000] {local_task_job_runner.py:222} INFO - ::endgroup::
