[2025-07-30T00:28:28.296+0000] {local_task_job_runner.py:120} INFO - ::group::Pre task execution logs
[2025-07-30T00:28:28.349+0000] {taskinstance.py:2073} INFO - Dependencies all met for dep_context=non-requeueable deps ti=<TaskInstance: drift_monitoring.check_drift_and_report scheduled__2025-07-29T23:00:00+00:00 [queued]>
[2025-07-30T00:28:28.359+0000] {taskinstance.py:2073} INFO - Dependencies all met for dep_context=requeueable deps ti=<TaskInstance: drift_monitoring.check_drift_and_report scheduled__2025-07-29T23:00:00+00:00 [queued]>
[2025-07-30T00:28:28.361+0000] {taskinstance.py:2303} INFO - Starting attempt 1 of 1
[2025-07-30T00:28:28.375+0000] {taskinstance.py:2327} INFO - Executing <Task(PythonOperator): check_drift_and_report> on 2025-07-29 23:00:00+00:00
[2025-07-30T00:28:28.393+0000] {standard_task_runner.py:90} INFO - Running: ['***', 'tasks', 'run', 'drift_monitoring', 'check_drift_and_report', 'scheduled__2025-07-29T23:00:00+00:00', '--job-id', '112', '--raw', '--subdir', 'DAGS_FOLDER/drift_monitoring.py', '--cfg-path', '/tmp/tmp_4t1hdr3']
[2025-07-30T00:28:28.397+0000] {logging_mixin.py:188} WARNING - /home/***/.local/lib/python3.12/site-packages/***/task/task_runner/standard_task_runner.py:61 DeprecationWarning: This process (pid=380) is multi-threaded, use of fork() may lead to deadlocks in the child.
[2025-07-30T00:28:28.398+0000] {standard_task_runner.py:91} INFO - Job 112: Subtask check_drift_and_report
[2025-07-30T00:28:28.398+0000] {standard_task_runner.py:63} INFO - Started process 416 to run task
[2025-07-30T00:28:28.420+0000] {logging_mixin.py:188} WARNING - /home/***/.local/lib/python3.12/site-packages/***/settings.py:195 DeprecationWarning: The sql_alchemy_conn option in [core] has been moved to the sql_alchemy_conn option in [database] - the old setting has been used, but please update your config.
[2025-07-30T00:28:28.470+0000] {task_command.py:426} INFO - Running <TaskInstance: drift_monitoring.check_drift_and_report scheduled__2025-07-29T23:00:00+00:00 [running]> on host 44c57df83f33
[2025-07-30T00:28:28.588+0000] {taskinstance.py:2644} INFO - Exporting env vars: AIRFLOW_CTX_DAG_OWNER='mlops' AIRFLOW_CTX_DAG_ID='drift_monitoring' AIRFLOW_CTX_TASK_ID='check_drift_and_report' AIRFLOW_CTX_EXECUTION_DATE='2025-07-29T23:00:00+00:00' AIRFLOW_CTX_TRY_NUMBER='1' AIRFLOW_CTX_DAG_RUN_ID='scheduled__2025-07-29T23:00:00+00:00'
[2025-07-30T00:28:28.589+0000] {taskinstance.py:430} INFO - ::endgroup::
[2025-07-30T00:28:28.632+0000] {drift_monitoring.py:239} INFO - Checking drift from 2025-07-22 23:28:28.632182+00:00 to 2025-07-29 23:28:28.632182+00:00
[2025-07-30T00:28:28.633+0000] {drift_monitoring.py:253} INFO - ðŸ“¥ Downloading predictions/date=2025-07-22/hour=23/prediction.parquet and targets/date=2025-07-22/hour=23/target.parquet
[2025-07-30T00:28:28.684+0000] {taskinstance.py:441} INFO - ::group::Post task execution logs
[2025-07-30T00:28:28.685+0000] {taskinstance.py:2890} ERROR - Task failed with exception
Traceback (most recent call last):
  File "/home/airflow/.local/lib/python3.12/site-packages/airflow/models/taskinstance.py", line 465, in _execute_task
    result = _execute_callable(context=context, **execute_callable_kwargs)
             ^^^^^^^^^^^^^^^^^^^^^^^^^^^^^^^^^^^^^^^^^^^^^^^^^^^^^^^^^^^^^
  File "/home/airflow/.local/lib/python3.12/site-packages/airflow/models/taskinstance.py", line 432, in _execute_callable
    return execute_callable(context=context, **execute_callable_kwargs)
           ^^^^^^^^^^^^^^^^^^^^^^^^^^^^^^^^^^^^^^^^^^^^^^^^^^^^^^^^^^^^
  File "/home/airflow/.local/lib/python3.12/site-packages/airflow/models/baseoperator.py", line 400, in wrapper
    return func(self, *args, **kwargs)
           ^^^^^^^^^^^^^^^^^^^^^^^^^^^
  File "/home/airflow/.local/lib/python3.12/site-packages/airflow/operators/python.py", line 235, in execute
    return_value = self.execute_callable()
                   ^^^^^^^^^^^^^^^^^^^^^^^
  File "/home/airflow/.local/lib/python3.12/site-packages/airflow/operators/python.py", line 252, in execute_callable
    return self.python_callable(*self.op_args, **self.op_kwargs)
           ^^^^^^^^^^^^^^^^^^^^^^^^^^^^^^^^^^^^^^^^^^^^^^^^^^^^^
  File "/opt/airflow/dags/drift_monitoring.py", line 255, in check_drift_and_report
    obj_pred = s3_client.get_object(Bucket=BUCKET_NAME, Key=key_pred)
               ^^^^^^^^^^^^^^^^^^^^^^^^^^^^^^^^^^^^^^^^^^^^^^^^^^^^^^
  File "/home/airflow/.local/lib/python3.12/site-packages/botocore/client.py", line 569, in _api_call
    return self._make_api_call(operation_name, kwargs)
           ^^^^^^^^^^^^^^^^^^^^^^^^^^^^^^^^^^^^^^^^^^^
  File "/home/airflow/.local/lib/python3.12/site-packages/botocore/client.py", line 1023, in _make_api_call
    raise error_class(parsed_response, operation_name)
botocore.errorfactory.NoSuchBucket: An error occurred (NoSuchBucket) when calling the GetObject operation: The specified bucket does not exist
[2025-07-30T00:28:28.703+0000] {taskinstance.py:1205} INFO - Marking task as FAILED. dag_id=drift_monitoring, task_id=check_drift_and_report, execution_date=20250729T230000, start_date=20250730T002828, end_date=20250730T002828
[2025-07-30T00:28:28.719+0000] {standard_task_runner.py:110} ERROR - Failed to execute job 112 for task check_drift_and_report (An error occurred (NoSuchBucket) when calling the GetObject operation: The specified bucket does not exist; 416)
[2025-07-30T00:28:28.773+0000] {local_task_job_runner.py:240} INFO - Task exited with return code 1
[2025-07-30T00:28:28.792+0000] {taskinstance.py:3482} INFO - 0 downstream tasks scheduled from follow-on schedule check
[2025-07-30T00:28:28.794+0000] {local_task_job_runner.py:222} INFO - ::endgroup::
