[2025-07-26T00:07:32.275+0000] {local_task_job_runner.py:120} INFO - ::group::Pre task execution logs
[2025-07-26T00:07:32.315+0000] {taskinstance.py:2073} INFO - Dependencies all met for dep_context=non-requeueable deps ti=<TaskInstance: training_pipeline.train_model manual__2025-07-26T00:07:15.346065+00:00 [queued]>
[2025-07-26T00:07:32.327+0000] {taskinstance.py:2073} INFO - Dependencies all met for dep_context=requeueable deps ti=<TaskInstance: training_pipeline.train_model manual__2025-07-26T00:07:15.346065+00:00 [queued]>
[2025-07-26T00:07:32.327+0000] {taskinstance.py:2303} INFO - Starting attempt 1 of 4
[2025-07-26T00:07:32.341+0000] {taskinstance.py:2327} INFO - Executing <Task(PythonOperator): train_model> on 2025-07-26 00:07:15.346065+00:00
[2025-07-26T00:07:32.358+0000] {logging_mixin.py:188} WARNING - /home/***/.local/lib/python3.12/site-packages/***/task/task_runner/standard_task_runner.py:61 DeprecationWarning: This process (pid=307) is multi-threaded, use of fork() may lead to deadlocks in the child.
[2025-07-26T00:07:32.357+0000] {standard_task_runner.py:90} INFO - Running: ['***', 'tasks', 'run', 'training_pipeline', 'train_model', 'manual__2025-07-26T00:07:15.346065+00:00', '--job-id', '5', '--raw', '--subdir', 'DAGS_FOLDER/training_pipeline.py', '--cfg-path', '/tmp/tmpb9rn5i5g']
[2025-07-26T00:07:32.360+0000] {standard_task_runner.py:63} INFO - Started process 324 to run task
[2025-07-26T00:07:32.360+0000] {standard_task_runner.py:91} INFO - Job 5: Subtask train_model
[2025-07-26T00:07:32.376+0000] {logging_mixin.py:188} WARNING - /home/***/.local/lib/python3.12/site-packages/***/settings.py:195 DeprecationWarning: The sql_alchemy_conn option in [core] has been moved to the sql_alchemy_conn option in [database] - the old setting has been used, but please update your config.
[2025-07-26T00:07:32.415+0000] {task_command.py:426} INFO - Running <TaskInstance: training_pipeline.train_model manual__2025-07-26T00:07:15.346065+00:00 [running]> on host 725668c9b196
[2025-07-26T00:07:32.504+0000] {taskinstance.py:2644} INFO - Exporting env vars: AIRFLOW_CTX_DAG_EMAIL='mlops_team@example.com' AIRFLOW_CTX_DAG_OWNER='mlops' AIRFLOW_CTX_DAG_ID='training_pipeline' AIRFLOW_CTX_TASK_ID='train_model' AIRFLOW_CTX_EXECUTION_DATE='2025-07-26T00:07:15.346065+00:00' AIRFLOW_CTX_TRY_NUMBER='1' AIRFLOW_CTX_DAG_RUN_ID='manual__2025-07-26T00:07:15.346065+00:00'
[2025-07-26T00:07:32.505+0000] {taskinstance.py:430} INFO - ::endgroup::
[2025-07-26T00:07:32.567+0000] {data_processing.py:38} INFO - Loaded 288 records from S3: data/historical_BTC_USD_20250726000724.csv
[2025-07-26T00:07:32.571+0000] {data_processing.py:82} INFO - Combined 288 records for BTC-USD
[2025-07-26T00:07:32.640+0000] {data_processing.py:160} INFO - Removed 50 rows with NaN values. Final shape: (238, 84)
[2025-07-26T00:07:32.645+0000] {logging_mixin.py:188} WARNING - /opt/***/src/data_processing.py:217 FutureWarning: DataFrame.fillna with 'method' is deprecated and will raise in a future version. Use obj.ffill() or obj.bfill() instead.
[2025-07-26T00:07:32.651+0000] {logging_mixin.py:188} WARNING - /opt/***/src/data_processing.py:175 FutureWarning: DataFrame.fillna with 'method' is deprecated and will raise in a future version. Use obj.ffill() or obj.bfill() instead.
[2025-07-26T00:07:32.653+0000] {data_processing.py:177} INFO - Prepared features: (238, 80), Target: (238,)
[2025-07-26T00:07:32.653+0000] {data_processing.py:178} INFO - Feature columns: 80
[2025-07-26T00:07:32.677+0000] {data_processing.py:194} INFO - Saved preprocessor to S3: s3://crypto-mlops-bucket/models/preprocessors/scaler_BTC_USD.pickle
[2025-07-26T00:07:32.767+0000] {logging_mixin.py:188} WARNING - 2025/07/26 00:07:32 WARNING mlflow.utils.git_utils: Failed to import Git (the Git executable is probably not on your PATH), so Git SHA is not available. Error: Failed to initialize: Bad git executable.
The git executable must be specified in one of the following ways:
    - be included in your $PATH
    - be set via $GIT_PYTHON_GIT_EXECUTABLE
    - explicitly set via git.refresh(<full-path-to-git-executable>)

All git commands will error until this is rectified.

This initial message can be silenced or aggravated in the future by setting the
$GIT_PYTHON_REFRESH environment variable. Use one of the following values:
    - quiet|q|silence|s|silent|none|n|0: for no message or exception
    - warn|w|warning|log|l|1: for a warning message (logging level CRITICAL, displayed by default)
    - error|e|exception|raise|r|2: for a raised exception

Example:
    export GIT_PYTHON_REFRESH=quiet
[2025-07-26T00:08:33.173+0000] {taskinstance.py:441} INFO - ::group::Post task execution logs
[2025-07-26T00:08:33.174+0000] {taskinstance.py:2890} ERROR - Task failed with exception
Traceback (most recent call last):
  File "/home/airflow/.local/lib/python3.12/site-packages/requests/adapters.py", line 667, in send
    resp = conn.urlopen(
           ^^^^^^^^^^^^^
  File "/home/airflow/.local/lib/python3.12/site-packages/urllib3/connectionpool.py", line 894, in urlopen
    return self.urlopen(
           ^^^^^^^^^^^^^
  File "/home/airflow/.local/lib/python3.12/site-packages/urllib3/connectionpool.py", line 894, in urlopen
    return self.urlopen(
           ^^^^^^^^^^^^^
  File "/home/airflow/.local/lib/python3.12/site-packages/urllib3/connectionpool.py", line 894, in urlopen
    return self.urlopen(
           ^^^^^^^^^^^^^
  [Previous line repeated 2 more times]
  File "/home/airflow/.local/lib/python3.12/site-packages/urllib3/connectionpool.py", line 884, in urlopen
    retries = retries.increment(method, url, response=response, _pool=self)
              ^^^^^^^^^^^^^^^^^^^^^^^^^^^^^^^^^^^^^^^^^^^^^^^^^^^^^^^^^^^^^
  File "/home/airflow/.local/lib/python3.12/site-packages/urllib3/util/retry.py", line 592, in increment
    raise MaxRetryError(_pool, url, error or ResponseError(cause))
urllib3.exceptions.MaxRetryError: HTTPConnectionPool(host='mlflow', port=5000): Max retries exceeded with url: /api/2.0/mlflow/runs/create (Caused by ResponseError('too many 500 error responses'))

During handling of the above exception, another exception occurred:

Traceback (most recent call last):
  File "/home/airflow/.local/lib/python3.12/site-packages/mlflow/utils/rest_utils.py", line 189, in http_request
    return _get_http_response_with_retries(
           ^^^^^^^^^^^^^^^^^^^^^^^^^^^^^^^^
  File "/home/airflow/.local/lib/python3.12/site-packages/mlflow/utils/request_utils.py", line 237, in _get_http_response_with_retries
    return session.request(method, url, allow_redirects=allow_redirects, **kwargs)
           ^^^^^^^^^^^^^^^^^^^^^^^^^^^^^^^^^^^^^^^^^^^^^^^^^^^^^^^^^^^^^^^^^^^^^^^
  File "/home/airflow/.local/lib/python3.12/site-packages/requests/sessions.py", line 589, in request
    resp = self.send(prep, **send_kwargs)
           ^^^^^^^^^^^^^^^^^^^^^^^^^^^^^^
  File "/home/airflow/.local/lib/python3.12/site-packages/requests/sessions.py", line 703, in send
    r = adapter.send(request, **kwargs)
        ^^^^^^^^^^^^^^^^^^^^^^^^^^^^^^^
  File "/home/airflow/.local/lib/python3.12/site-packages/requests/adapters.py", line 691, in send
    raise RetryError(e, request=request)
requests.exceptions.RetryError: HTTPConnectionPool(host='mlflow', port=5000): Max retries exceeded with url: /api/2.0/mlflow/runs/create (Caused by ResponseError('too many 500 error responses'))

During handling of the above exception, another exception occurred:

Traceback (most recent call last):
  File "/home/airflow/.local/lib/python3.12/site-packages/airflow/models/taskinstance.py", line 465, in _execute_task
    result = _execute_callable(context=context, **execute_callable_kwargs)
             ^^^^^^^^^^^^^^^^^^^^^^^^^^^^^^^^^^^^^^^^^^^^^^^^^^^^^^^^^^^^^
  File "/home/airflow/.local/lib/python3.12/site-packages/airflow/models/taskinstance.py", line 432, in _execute_callable
    return execute_callable(context=context, **execute_callable_kwargs)
           ^^^^^^^^^^^^^^^^^^^^^^^^^^^^^^^^^^^^^^^^^^^^^^^^^^^^^^^^^^^^
  File "/home/airflow/.local/lib/python3.12/site-packages/airflow/models/baseoperator.py", line 400, in wrapper
    return func(self, *args, **kwargs)
           ^^^^^^^^^^^^^^^^^^^^^^^^^^^
  File "/home/airflow/.local/lib/python3.12/site-packages/airflow/operators/python.py", line 235, in execute
    return_value = self.execute_callable()
                   ^^^^^^^^^^^^^^^^^^^^^^^
  File "/home/airflow/.local/lib/python3.12/site-packages/airflow/operators/python.py", line 252, in execute_callable
    return self.python_callable(*self.op_args, **self.op_kwargs)
           ^^^^^^^^^^^^^^^^^^^^^^^^^^^^^^^^^^^^^^^^^^^^^^^^^^^^^
  File "/opt/airflow/dags/training_pipeline.py", line 117, in train
    result = model.train_model(
             ^^^^^^^^^^^^^^^^^^
  File "/opt/airflow/src/model.py", line 88, in train_model
    with mlflow.start_run(run_name=f"lightgbm_training_{symbol}_{datetime.now().strftime('%Y%m%d_%H%M%S')}"):
         ^^^^^^^^^^^^^^^^^^^^^^^^^^^^^^^^^^^^^^^^^^^^^^^^^^^^^^^^^^^^^^^^^^^^^^^^^^^^^^^^^^^^^^^^^^^^^^^^^^^
  File "/home/airflow/.local/lib/python3.12/site-packages/mlflow/tracking/fluent.py", line 418, in start_run
    active_run_obj = client.create_run(
                     ^^^^^^^^^^^^^^^^^^
  File "/home/airflow/.local/lib/python3.12/site-packages/mlflow/tracking/client.py", line 392, in create_run
    return self._tracking_client.create_run(experiment_id, start_time, tags, run_name)
           ^^^^^^^^^^^^^^^^^^^^^^^^^^^^^^^^^^^^^^^^^^^^^^^^^^^^^^^^^^^^^^^^^^^^^^^^^^^
  File "/home/airflow/.local/lib/python3.12/site-packages/mlflow/tracking/_tracking_service/client.py", line 167, in create_run
    return self.store.create_run(
           ^^^^^^^^^^^^^^^^^^^^^^
  File "/home/airflow/.local/lib/python3.12/site-packages/mlflow/store/tracking/rest_store.py", line 209, in create_run
    response_proto = self._call_endpoint(CreateRun, req_body)
                     ^^^^^^^^^^^^^^^^^^^^^^^^^^^^^^^^^^^^^^^^
  File "/home/airflow/.local/lib/python3.12/site-packages/mlflow/store/tracking/rest_store.py", line 82, in _call_endpoint
    return call_endpoint(self.get_host_creds(), endpoint, method, json_body, response_proto)
           ^^^^^^^^^^^^^^^^^^^^^^^^^^^^^^^^^^^^^^^^^^^^^^^^^^^^^^^^^^^^^^^^^^^^^^^^^^^^^^^^^
  File "/home/airflow/.local/lib/python3.12/site-packages/mlflow/utils/rest_utils.py", line 368, in call_endpoint
    response = http_request(**call_kwargs)
               ^^^^^^^^^^^^^^^^^^^^^^^^^^^
  File "/home/airflow/.local/lib/python3.12/site-packages/mlflow/utils/rest_utils.py", line 212, in http_request
    raise MlflowException(f"API request to {url} failed with exception {e}")
mlflow.exceptions.MlflowException: API request to http://mlflow:5000/api/2.0/mlflow/runs/create failed with exception HTTPConnectionPool(host='mlflow', port=5000): Max retries exceeded with url: /api/2.0/mlflow/runs/create (Caused by ResponseError('too many 500 error responses'))
[2025-07-26T00:08:33.203+0000] {taskinstance.py:1205} INFO - Marking task as UP_FOR_RETRY. dag_id=training_pipeline, task_id=train_model, execution_date=20250726T000715, start_date=20250726T000732, end_date=20250726T000833
[2025-07-26T00:08:33.219+0000] {logging_mixin.py:188} WARNING - /home/***/.local/lib/python3.12/site-packages/***/utils/email.py:154 RemovedInAirflow3Warning: Fetching SMTP credentials from configuration variables will be deprecated in a future release. Please set credentials using a connection instead.
[2025-07-26T00:08:33.220+0000] {configuration.py:1050} WARNING - section/key [smtp/smtp_user] not found in config
[2025-07-26T00:08:33.221+0000] {email.py:271} INFO - Email alerting: attempt 1
[2025-07-26T00:08:33.229+0000] {configuration.py:1050} WARNING - section/key [smtp/smtp_user] not found in config
[2025-07-26T00:08:33.230+0000] {email.py:271} INFO - Email alerting: attempt 1
[2025-07-26T00:08:33.232+0000] {taskinstance.py:879} ERROR - Failed to send email to: ['mlops_team@example.com']
Traceback (most recent call last):
  File "/home/airflow/.local/lib/python3.12/site-packages/requests/adapters.py", line 667, in send
    resp = conn.urlopen(
           ^^^^^^^^^^^^^
  File "/home/airflow/.local/lib/python3.12/site-packages/urllib3/connectionpool.py", line 894, in urlopen
    return self.urlopen(
           ^^^^^^^^^^^^^
  File "/home/airflow/.local/lib/python3.12/site-packages/urllib3/connectionpool.py", line 894, in urlopen
    return self.urlopen(
           ^^^^^^^^^^^^^
  File "/home/airflow/.local/lib/python3.12/site-packages/urllib3/connectionpool.py", line 894, in urlopen
    return self.urlopen(
           ^^^^^^^^^^^^^
  [Previous line repeated 2 more times]
  File "/home/airflow/.local/lib/python3.12/site-packages/urllib3/connectionpool.py", line 884, in urlopen
    retries = retries.increment(method, url, response=response, _pool=self)
              ^^^^^^^^^^^^^^^^^^^^^^^^^^^^^^^^^^^^^^^^^^^^^^^^^^^^^^^^^^^^^
  File "/home/airflow/.local/lib/python3.12/site-packages/urllib3/util/retry.py", line 592, in increment
    raise MaxRetryError(_pool, url, error or ResponseError(cause))
urllib3.exceptions.MaxRetryError: HTTPConnectionPool(host='mlflow', port=5000): Max retries exceeded with url: /api/2.0/mlflow/runs/create (Caused by ResponseError('too many 500 error responses'))

During handling of the above exception, another exception occurred:

Traceback (most recent call last):
  File "/home/airflow/.local/lib/python3.12/site-packages/mlflow/utils/rest_utils.py", line 189, in http_request
    return _get_http_response_with_retries(
           ^^^^^^^^^^^^^^^^^^^^^^^^^^^^^^^^
  File "/home/airflow/.local/lib/python3.12/site-packages/mlflow/utils/request_utils.py", line 237, in _get_http_response_with_retries
    return session.request(method, url, allow_redirects=allow_redirects, **kwargs)
           ^^^^^^^^^^^^^^^^^^^^^^^^^^^^^^^^^^^^^^^^^^^^^^^^^^^^^^^^^^^^^^^^^^^^^^^
  File "/home/airflow/.local/lib/python3.12/site-packages/requests/sessions.py", line 589, in request
    resp = self.send(prep, **send_kwargs)
           ^^^^^^^^^^^^^^^^^^^^^^^^^^^^^^
  File "/home/airflow/.local/lib/python3.12/site-packages/requests/sessions.py", line 703, in send
    r = adapter.send(request, **kwargs)
        ^^^^^^^^^^^^^^^^^^^^^^^^^^^^^^^
  File "/home/airflow/.local/lib/python3.12/site-packages/requests/adapters.py", line 691, in send
    raise RetryError(e, request=request)
requests.exceptions.RetryError: HTTPConnectionPool(host='mlflow', port=5000): Max retries exceeded with url: /api/2.0/mlflow/runs/create (Caused by ResponseError('too many 500 error responses'))

During handling of the above exception, another exception occurred:

Traceback (most recent call last):
  File "/home/airflow/.local/lib/python3.12/site-packages/airflow/models/taskinstance.py", line 2476, in _run_raw_task
    self._execute_task_with_callbacks(context, test_mode, session=session)
  File "/home/airflow/.local/lib/python3.12/site-packages/airflow/models/taskinstance.py", line 2663, in _execute_task_with_callbacks
    result = self._execute_task(context, task_orig)
             ^^^^^^^^^^^^^^^^^^^^^^^^^^^^^^^^^^^^^^
  File "/home/airflow/.local/lib/python3.12/site-packages/airflow/models/taskinstance.py", line 2686, in _execute_task
    return _execute_task(self, context, task_orig)
           ^^^^^^^^^^^^^^^^^^^^^^^^^^^^^^^^^^^^^^^
  File "/home/airflow/.local/lib/python3.12/site-packages/airflow/models/taskinstance.py", line 465, in _execute_task
    result = _execute_callable(context=context, **execute_callable_kwargs)
             ^^^^^^^^^^^^^^^^^^^^^^^^^^^^^^^^^^^^^^^^^^^^^^^^^^^^^^^^^^^^^
  File "/home/airflow/.local/lib/python3.12/site-packages/airflow/models/taskinstance.py", line 432, in _execute_callable
    return execute_callable(context=context, **execute_callable_kwargs)
           ^^^^^^^^^^^^^^^^^^^^^^^^^^^^^^^^^^^^^^^^^^^^^^^^^^^^^^^^^^^^
  File "/home/airflow/.local/lib/python3.12/site-packages/airflow/models/baseoperator.py", line 400, in wrapper
    return func(self, *args, **kwargs)
           ^^^^^^^^^^^^^^^^^^^^^^^^^^^
  File "/home/airflow/.local/lib/python3.12/site-packages/airflow/operators/python.py", line 235, in execute
    return_value = self.execute_callable()
                   ^^^^^^^^^^^^^^^^^^^^^^^
  File "/home/airflow/.local/lib/python3.12/site-packages/airflow/operators/python.py", line 252, in execute_callable
    return self.python_callable(*self.op_args, **self.op_kwargs)
           ^^^^^^^^^^^^^^^^^^^^^^^^^^^^^^^^^^^^^^^^^^^^^^^^^^^^^
  File "/opt/airflow/dags/training_pipeline.py", line 117, in train
    result = model.train_model(
             ^^^^^^^^^^^^^^^^^^
  File "/opt/airflow/src/model.py", line 88, in train_model
    with mlflow.start_run(run_name=f"lightgbm_training_{symbol}_{datetime.now().strftime('%Y%m%d_%H%M%S')}"):
         ^^^^^^^^^^^^^^^^^^^^^^^^^^^^^^^^^^^^^^^^^^^^^^^^^^^^^^^^^^^^^^^^^^^^^^^^^^^^^^^^^^^^^^^^^^^^^^^^^^^
  File "/home/airflow/.local/lib/python3.12/site-packages/mlflow/tracking/fluent.py", line 418, in start_run
    active_run_obj = client.create_run(
                     ^^^^^^^^^^^^^^^^^^
  File "/home/airflow/.local/lib/python3.12/site-packages/mlflow/tracking/client.py", line 392, in create_run
    return self._tracking_client.create_run(experiment_id, start_time, tags, run_name)
           ^^^^^^^^^^^^^^^^^^^^^^^^^^^^^^^^^^^^^^^^^^^^^^^^^^^^^^^^^^^^^^^^^^^^^^^^^^^
  File "/home/airflow/.local/lib/python3.12/site-packages/mlflow/tracking/_tracking_service/client.py", line 167, in create_run
    return self.store.create_run(
           ^^^^^^^^^^^^^^^^^^^^^^
  File "/home/airflow/.local/lib/python3.12/site-packages/mlflow/store/tracking/rest_store.py", line 209, in create_run
    response_proto = self._call_endpoint(CreateRun, req_body)
                     ^^^^^^^^^^^^^^^^^^^^^^^^^^^^^^^^^^^^^^^^
  File "/home/airflow/.local/lib/python3.12/site-packages/mlflow/store/tracking/rest_store.py", line 82, in _call_endpoint
    return call_endpoint(self.get_host_creds(), endpoint, method, json_body, response_proto)
           ^^^^^^^^^^^^^^^^^^^^^^^^^^^^^^^^^^^^^^^^^^^^^^^^^^^^^^^^^^^^^^^^^^^^^^^^^^^^^^^^^
  File "/home/airflow/.local/lib/python3.12/site-packages/mlflow/utils/rest_utils.py", line 368, in call_endpoint
    response = http_request(**call_kwargs)
               ^^^^^^^^^^^^^^^^^^^^^^^^^^^
  File "/home/airflow/.local/lib/python3.12/site-packages/mlflow/utils/rest_utils.py", line 212, in http_request
    raise MlflowException(f"API request to {url} failed with exception {e}")
mlflow.exceptions.MlflowException: API request to http://mlflow:5000/api/2.0/mlflow/runs/create failed with exception HTTPConnectionPool(host='mlflow', port=5000): Max retries exceeded with url: /api/2.0/mlflow/runs/create (Caused by ResponseError('too many 500 error responses'))

During handling of the above exception, another exception occurred:

Traceback (most recent call last):
  File "/home/airflow/.local/lib/python3.12/site-packages/airflow/models/taskinstance.py", line 1063, in _email_alert
    send_email(task.email, subject, html_content)
  File "/home/airflow/.local/lib/python3.12/site-packages/airflow/utils/email.py", line 80, in send_email
    return backend(
           ^^^^^^^^
  File "/home/airflow/.local/lib/python3.12/site-packages/airflow/utils/email.py", line 154, in send_email_smtp
    send_mime_email(e_from=mail_from, e_to=recipients, mime_msg=msg, conn_id=conn_id, dryrun=dryrun)
  File "/home/airflow/.local/lib/python3.12/site-packages/airflow/utils/email.py", line 273, in send_mime_email
    smtp_conn = _get_smtp_connection(smtp_host, smtp_port, smtp_timeout, smtp_ssl)
                ^^^^^^^^^^^^^^^^^^^^^^^^^^^^^^^^^^^^^^^^^^^^^^^^^^^^^^^^^^^^^^^^^^
  File "/home/airflow/.local/lib/python3.12/site-packages/airflow/utils/email.py", line 317, in _get_smtp_connection
    return smtplib.SMTP(host=host, port=port, timeout=timeout)
           ^^^^^^^^^^^^^^^^^^^^^^^^^^^^^^^^^^^^^^^^^^^^^^^^^^^
  File "/usr/local/lib/python3.12/smtplib.py", line 255, in __init__
    (code, msg) = self.connect(host, port)
                  ^^^^^^^^^^^^^^^^^^^^^^^^
  File "/usr/local/lib/python3.12/smtplib.py", line 341, in connect
    self.sock = self._get_socket(host, port, self.timeout)
                ^^^^^^^^^^^^^^^^^^^^^^^^^^^^^^^^^^^^^^^^^^
  File "/usr/local/lib/python3.12/smtplib.py", line 312, in _get_socket
    return socket.create_connection((host, port), timeout,
           ^^^^^^^^^^^^^^^^^^^^^^^^^^^^^^^^^^^^^^^^^^^^^^^
  File "/usr/local/lib/python3.12/socket.py", line 852, in create_connection
    raise exceptions[0]
  File "/usr/local/lib/python3.12/socket.py", line 837, in create_connection
    sock.connect(sa)
ConnectionRefusedError: [Errno 111] Connection refused

During handling of the above exception, another exception occurred:

Traceback (most recent call last):
  File "/home/airflow/.local/lib/python3.12/site-packages/airflow/models/taskinstance.py", line 877, in _handle_failure
    task_instance.email_alert(error, failure_context["task"])
  File "/home/airflow/.local/lib/python3.12/site-packages/airflow/models/taskinstance.py", line 3148, in email_alert
    _email_alert(task_instance=self, exception=exception, task=task)
  File "/home/airflow/.local/lib/python3.12/site-packages/airflow/models/taskinstance.py", line 1065, in _email_alert
    send_email(task.email, subject, html_content_err)
  File "/home/airflow/.local/lib/python3.12/site-packages/airflow/utils/email.py", line 80, in send_email
    return backend(
           ^^^^^^^^
  File "/home/airflow/.local/lib/python3.12/site-packages/airflow/utils/email.py", line 154, in send_email_smtp
    send_mime_email(e_from=mail_from, e_to=recipients, mime_msg=msg, conn_id=conn_id, dryrun=dryrun)
  File "/home/airflow/.local/lib/python3.12/site-packages/airflow/utils/email.py", line 273, in send_mime_email
    smtp_conn = _get_smtp_connection(smtp_host, smtp_port, smtp_timeout, smtp_ssl)
                ^^^^^^^^^^^^^^^^^^^^^^^^^^^^^^^^^^^^^^^^^^^^^^^^^^^^^^^^^^^^^^^^^^
  File "/home/airflow/.local/lib/python3.12/site-packages/airflow/utils/email.py", line 317, in _get_smtp_connection
    return smtplib.SMTP(host=host, port=port, timeout=timeout)
           ^^^^^^^^^^^^^^^^^^^^^^^^^^^^^^^^^^^^^^^^^^^^^^^^^^^
  File "/usr/local/lib/python3.12/smtplib.py", line 255, in __init__
    (code, msg) = self.connect(host, port)
                  ^^^^^^^^^^^^^^^^^^^^^^^^
  File "/usr/local/lib/python3.12/smtplib.py", line 341, in connect
    self.sock = self._get_socket(host, port, self.timeout)
                ^^^^^^^^^^^^^^^^^^^^^^^^^^^^^^^^^^^^^^^^^^
  File "/usr/local/lib/python3.12/smtplib.py", line 312, in _get_socket
    return socket.create_connection((host, port), timeout,
           ^^^^^^^^^^^^^^^^^^^^^^^^^^^^^^^^^^^^^^^^^^^^^^^
  File "/usr/local/lib/python3.12/socket.py", line 852, in create_connection
    raise exceptions[0]
  File "/usr/local/lib/python3.12/socket.py", line 837, in create_connection
    sock.connect(sa)
ConnectionRefusedError: [Errno 111] Connection refused
[2025-07-26T00:08:33.256+0000] {standard_task_runner.py:110} ERROR - Failed to execute job 5 for task train_model (API request to http://mlflow:5000/api/2.0/mlflow/runs/create failed with exception HTTPConnectionPool(host='mlflow', port=5000): Max retries exceeded with url: /api/2.0/mlflow/runs/create (Caused by ResponseError('too many 500 error responses')); 324)
[2025-07-26T00:08:33.298+0000] {local_task_job_runner.py:240} INFO - Task exited with return code 1
[2025-07-26T00:08:33.322+0000] {taskinstance.py:3482} INFO - 0 downstream tasks scheduled from follow-on schedule check
[2025-07-26T00:08:33.325+0000] {local_task_job_runner.py:222} INFO - ::endgroup::
