[2025-07-26T20:20:13.724+0000] {local_task_job_runner.py:120} INFO - ::group::Pre task execution logs
[2025-07-26T20:20:13.773+0000] {taskinstance.py:2073} INFO - Dependencies all met for dep_context=non-requeueable deps ti=<TaskInstance: training_pipeline.train_model manual__2025-07-26T20:16:53.092380+00:00 [queued]>
[2025-07-26T20:20:13.785+0000] {taskinstance.py:2073} INFO - Dependencies all met for dep_context=requeueable deps ti=<TaskInstance: training_pipeline.train_model manual__2025-07-26T20:16:53.092380+00:00 [queued]>
[2025-07-26T20:20:13.787+0000] {taskinstance.py:2303} INFO - Starting attempt 2 of 4
[2025-07-26T20:20:13.806+0000] {taskinstance.py:2327} INFO - Executing <Task(PythonOperator): train_model> on 2025-07-26 20:16:53.092380+00:00
[2025-07-26T20:20:13.829+0000] {logging_mixin.py:188} WARNING - /home/***/.local/lib/python3.12/site-packages/***/task/task_runner/standard_task_runner.py:61 DeprecationWarning: This process (pid=493) is multi-threaded, use of fork() may lead to deadlocks in the child.
[2025-07-26T20:20:13.826+0000] {standard_task_runner.py:90} INFO - Running: ['***', 'tasks', 'run', 'training_pipeline', 'train_model', 'manual__2025-07-26T20:16:53.092380+00:00', '--job-id', '6', '--raw', '--subdir', 'DAGS_FOLDER/training_pipeline.py', '--cfg-path', '/tmp/tmpl5uu4yce']
[2025-07-26T20:20:13.831+0000] {standard_task_runner.py:63} INFO - Started process 510 to run task
[2025-07-26T20:20:13.832+0000] {standard_task_runner.py:91} INFO - Job 6: Subtask train_model
[2025-07-26T20:20:13.855+0000] {logging_mixin.py:188} WARNING - /home/***/.local/lib/python3.12/site-packages/***/settings.py:195 DeprecationWarning: The sql_alchemy_conn option in [core] has been moved to the sql_alchemy_conn option in [database] - the old setting has been used, but please update your config.
[2025-07-26T20:20:13.915+0000] {task_command.py:426} INFO - Running <TaskInstance: training_pipeline.train_model manual__2025-07-26T20:16:53.092380+00:00 [running]> on host 51a89c11afaa
[2025-07-26T20:20:14.042+0000] {taskinstance.py:2644} INFO - Exporting env vars: AIRFLOW_CTX_DAG_EMAIL='mlops_team@example.com' AIRFLOW_CTX_DAG_OWNER='mlops' AIRFLOW_CTX_DAG_ID='training_pipeline' AIRFLOW_CTX_TASK_ID='train_model' AIRFLOW_CTX_EXECUTION_DATE='2025-07-26T20:16:53.092380+00:00' AIRFLOW_CTX_TRY_NUMBER='2' AIRFLOW_CTX_DAG_RUN_ID='manual__2025-07-26T20:16:53.092380+00:00'
[2025-07-26T20:20:14.045+0000] {taskinstance.py:430} INFO - ::endgroup::
[2025-07-26T20:20:14.162+0000] {data_processing.py:38} INFO - Loaded 288 records from S3: data/historical_BTC_USD_20250726201702.csv
[2025-07-26T20:20:14.166+0000] {data_processing.py:82} INFO - Combined 288 records for BTC-USD
[2025-07-26T20:20:14.234+0000] {data_processing.py:160} INFO - Removed 50 rows with NaN values. Final shape: (238, 84)
[2025-07-26T20:20:14.239+0000] {logging_mixin.py:188} WARNING - /opt/***/src/data_processing.py:217 FutureWarning: DataFrame.fillna with 'method' is deprecated and will raise in a future version. Use obj.ffill() or obj.bfill() instead.
[2025-07-26T20:20:14.245+0000] {logging_mixin.py:188} WARNING - /opt/***/src/data_processing.py:175 FutureWarning: DataFrame.fillna with 'method' is deprecated and will raise in a future version. Use obj.ffill() or obj.bfill() instead.
[2025-07-26T20:20:14.247+0000] {data_processing.py:177} INFO - Prepared features: (238, 80), Target: (238,)
[2025-07-26T20:20:14.247+0000] {data_processing.py:178} INFO - Feature columns: 80
[2025-07-26T20:20:14.274+0000] {data_processing.py:194} INFO - Saved preprocessor to S3: s3://crypto-mlops-bucket/models/preprocessors/scaler_BTC_USD.pickle
[2025-07-26T20:20:14.366+0000] {logging_mixin.py:188} WARNING - 2025/07/26 20:20:14 WARNING mlflow.utils.git_utils: Failed to import Git (the Git executable is probably not on your PATH), so Git SHA is not available. Error: Failed to initialize: Bad git executable.
The git executable must be specified in one of the following ways:
    - be included in your $PATH
    - be set via $GIT_PYTHON_GIT_EXECUTABLE
    - explicitly set via git.refresh(<full-path-to-git-executable>)

All git commands will error until this is rectified.

This initial message can be silenced or aggravated in the future by setting the
$GIT_PYTHON_REFRESH environment variable. Use one of the following values:
    - quiet|q|silence|s|silent|none|n|0: for no message or exception
    - warn|w|warning|log|l|1: for a warning message (logging level CRITICAL, displayed by default)
    - error|e|exception|raise|r|2: for a raised exception

Example:
    export GIT_PYTHON_REFRESH=quiet
[2025-07-26T20:20:14.439+0000] {connectionpool.py:824} WARNING - Retrying (JitteredRetry(total=4, connect=4, read=5, redirect=5, status=5)) after connection broken by 'NewConnectionError('<urllib3.connection.HTTPConnection object at 0x7fef8267afc0>: Failed to establish a new connection: [Errno 111] Connection refused')': /api/2.0/mlflow/runs/create
[2025-07-26T20:20:16.132+0000] {connectionpool.py:824} WARNING - Retrying (JitteredRetry(total=3, connect=3, read=5, redirect=5, status=5)) after connection broken by 'NewConnectionError('<urllib3.connection.HTTPConnection object at 0x7fefc3598230>: Failed to establish a new connection: [Errno 111] Connection refused')': /api/2.0/mlflow/runs/create
[2025-07-26T20:20:24.143+0000] {connectionpool.py:824} WARNING - Retrying (JitteredRetry(total=2, connect=2, read=5, redirect=5, status=5)) after connection broken by 'NewConnectionError('<urllib3.connection.HTTPConnection object at 0x7fefc3599160>: Failed to establish a new connection: [Errno 111] Connection refused')': /api/2.0/mlflow/runs/create
[2025-07-26T20:20:40.168+0000] {connectionpool.py:824} WARNING - Retrying (JitteredRetry(total=1, connect=1, read=5, redirect=5, status=5)) after connection broken by 'NewConnectionError('<urllib3.connection.HTTPConnection object at 0x7fefc3599850>: Failed to establish a new connection: [Errno 111] Connection refused')': /api/2.0/mlflow/runs/create
